File: Datos_proyecto_final/NaCl_TT_300/NaCl_TT_300.csv
[Measurement conditions]
Sample identification,NaCl_TT_300
Comment,
Anode material,Cu
K-Alpha1 wavelength,1.5405980
K-Alpha2 wavelength,1.5444260
Ratio K-Alpha2/K-Alpha1,0.500
Divergence slit,Fixed,0.76mm
Monochromator used,NO
Generator voltage, 40
Tube current,  8
File date and time,28/Jun./2022 02:03
Unit cell,
h k l, 0 0 0
Scan axis,Gonio
Scan range,5.000000000,110.013276160
Scan step size,0.0217329
No. of points, 4832
Scan type,CONTINUOUS
Time per step,49.470
[Scan points]
Angle,Intensity
5.010866440,3868.0
5.097797960,3654.0
5.184729480,3569.0
5.271661000,3419.0
5.358592520,3313.0
5.445524040,3199.0
5.532455560,3024.0
5.619387080,2843.0
5.706318600,2850.0
5.793250120,2823.0
5.880181640,2715.0
5.967113160,2662.0
6.054044680,2521.0
6.140976200,2673.0
6.227907720,2485.0
6.314839240,2480.0
6.401770760,2494.0
6.488702280,2411.0
6.575633800,2460.0
6.662565320,2413.0
6.749496840,2385.0
6.836428360,2408.0
6.923359880,2358.0
7.010291400,2394.0
7.097222920,2343.0
7.184154440,2426.0
7.271085960,2366.0
7.358017480,2374.0
7.444949000,2362.0
7.531880520,2439.0
7.618812040,2382.0
7.705743560,2411.0
7.792675080,2325.0
7.879606600,2336.0
7.966538120,2404.0
8.053469640,2393.0
8.140401160,2343.0
8.227332680,2328.0
8.314264200,2385.0
8.401195720,2361.0
8.488127240,2381.0
8.575058760,2334.0
8.661990280,2333.0
8.748921800,2378.0
8.835853320,2310.0
8.922784840,2423.0
9.009716360,2345.0
9.096647880,2354.0
9.183579400,2390.0
9.270510920,2504.0
9.357442440,2398.0
9.444373960,2411.0
9.531305480,2415.0
9.618237000,2327.0
9.705168520,2440.0
9.792100040,2462.0
9.879031560,2375.0
9.965963080,2413.0
10.052894600,2514.0
10.139826120,2507.0
10.226757640,2411.0
10.313689160,2470.0
10.400620680,2370.0
10.487552200,2376.0
10.574483720,2469.0
10.661415240,2445.0
10.748346760,2403.0
10.835278280,2520.0
10.922209800,2325.0
11.009141320,2483.0
11.096072840,2392.0
11.183004360,2352.0
11.269935880,2382.0
11.356867400,2419.0
11.443798920,2540.0
11.530730440,2497.0
11.617661960,2430.0
11.704593480,2432.0
11.791525000,2462.0
11.878456520,2417.0
11.965388040,2378.0
12.052319560,2393.0
12.139251080,2349.0
12.226182600,2470.0
12.313114120,2426.0
12.400045640,2423.0
12.486977160,2510.0
12.573908680,2376.0
12.660840200,2527.0
12.747771720,2288.0
12.834703240,2401.0
12.921634760,2474.0
13.008566280,2323.0
13.095497800,2390.0
13.182429320,2314.0
13.269360840,2253.0
13.356292360,2307.0
13.443223880,2271.0
13.530155400,2410.0
13.617086920,2282.0
13.704018440,2214.0
13.790949960,2302.0
13.877881480,2138.0
13.964813000,2221.0
14.051744520,2212.0
14.138676040,2224.0
14.225607560,2240.0
14.312539080,2177.0
14.399470600,2186.0
14.486402120,2255.0
14.573333640,2236.0
14.660265160,2249.0
14.747196680,2311.0
14.834128200,2204.0
14.921059720,2053.0
15.007991240,2069.0
15.094922760,2094.0
15.181854280,2091.0
15.268785800,2052.0
15.355717320,2041.0
15.442648840,2030.0
15.529580360,1976.0
15.616511880,2008.0
15.703443400,1970.0
15.790374920,1884.0
15.877306440,1932.0
15.964237960,1866.0
16.051169480,1848.0
16.138101000,1903.0
16.225032520,1800.0
16.311964040,1812.0
16.398895560,1792.0
16.485827080,1776.0
16.572758600,1876.0
16.659690120,1752.0
16.746621640,1821.0
16.833553160,1728.0
16.920484680,1685.0
17.007416200,1747.0
17.094347720,1714.0
17.181279240,1748.0
17.268210760,1670.0
17.355142280,1731.0
17.442073800,1732.0
17.529005320,1755.0
17.615936840,1636.0
17.702868360,1574.0
17.789799880,1562.0
17.876731400,1629.0
17.963662920,1515.0
18.050594440,1579.0
18.137525960,1560.0
18.224457480,1579.0
18.311389000,1592.0
18.398320520,1606.0
18.485252040,1566.0
18.572183560,1543.0
18.659115080,1501.0
18.746046600,1460.0
18.832978120,1464.0
18.919909640,1454.0
19.006841160,1465.0
19.093772680,1493.0
19.180704200,1490.0
19.267635720,1455.0
19.354567240,1358.0
19.441498760,1462.0
19.528430280,1419.0
19.615361800,1308.0
19.702293320,1407.0
19.789224840,1416.0
19.876156360,1318.0
19.963087880,1418.0
20.050019400,1271.0
20.136950920,1349.0
20.223882440,1282.0
20.310813960,1357.0
20.397745480,1322.0
20.484677000,1349.0
20.571608520,1306.0
20.658540040,1293.0
20.745471560,1313.0
20.832403080,1336.0
20.919334600,1268.0
21.006266120,1208.0
21.093197640,1250.0
21.180129160,1176.0
21.267060680,1220.0
21.353992200,1185.0
21.440923720,1247.0
21.527855240,1215.0
21.614786760,1199.0
21.701718280,1137.0
21.788649800,1150.0
21.875581320,1117.0
21.962512840,1100.0
22.049444360,1117.0
22.136375880,1086.0
22.223307400,1183.0
22.310238920,1040.0
22.397170440,1114.0
22.484101960,1067.0
22.571033480,1075.0
22.657965000,1078.0
22.744896520,1082.0
22.831828040,1104.0
22.918759560,1046.0
23.005691080,1013.0
23.092622600,988.0
23.179554120,985.0
23.266485640,1010.0
23.353417160,1063.0
23.440348680,996.0
23.527280200,1020.0
23.614211720,985.0
23.701143240,958.0
23.788074760,1038.0
23.875006280,999.0
23.961937800,944.0
24.048869320,935.0
24.135800840,967.0
24.222732360,983.0
24.309663880,959.0
24.396595400,890.0
24.483526920,913.0
24.570458440,922.0
24.657389960,936.0
24.744321480,862.0
24.831253000,953.0
24.918184520,889.0
25.005116040,912.0
25.092047560,969.0
25.178979080,1059.0
25.265910600,1123.0
25.352842120,1385.0
25.439773640,1656.0
25.526705160,1323.0
25.613636680,1147.0
25.700568200,1032.0
25.787499720,904.0
25.874431240,898.0
25.961362760,827.0
26.048294280,912.0
26.135225800,858.0
26.222157320,844.0
26.309088840,860.0
26.396020360,812.0
26.482951880,795.0
26.569883400,812.0
26.656814920,804.0
26.743746440,831.0
26.830677960,801.0
26.917609480,795.0
27.004541000,760.0
27.091472520,878.0
27.178404040,1146.0
27.265335560,2098.0
27.352267080,4650.0
27.439198600,2161.0
27.526130120,894.0
27.613061640,862.0
27.699993160,756.0
27.786924680,751.0
27.873856200,758.0
27.960787720,774.0
28.047719240,781.0
28.134650760,758.0
28.221582280,738.0
28.308513800,763.0
28.395445320,803.0
28.482376840,943.0
28.569308360,1642.0
28.656239880,825.0
28.743171400,739.0
28.830102920,735.0
28.917034440,740.0
29.003965960,724.0
29.090897480,776.0
29.177829000,737.0
29.264760520,753.0
29.351692040,793.0
29.438623560,793.0
29.525555080,856.0
29.612486600,879.0
29.699418120,916.0
29.786349640,774.0
29.873281160,800.0
29.960212680,751.0
30.047144200,720.0
30.134075720,726.0
30.221007240,710.0
30.307938760,702.0
30.394870280,795.0
30.481801800,864.0
30.568733320,1054.0
30.655664840,1294.0
30.742596360,1351.0
30.829527880,1361.0
30.916459400,1361.0
31.003390920,1462.0
31.090322440,1603.0
31.177253960,2040.0
31.264185480,2957.0
31.351117000,3583.0
31.438048520,4940.0
31.524980040,13043.0
31.611911560,66838.0
31.698843080,218487.0
31.785774600,88540.0
31.872706120,7652.0
31.959637640,4446.0
32.046569160,2977.0
32.133500680,1846.0
32.220432200,1464.0
32.307363720,1415.0
32.394295240,1287.0
32.481226760,1194.0
32.568158280,1172.0
32.655089800,1114.0
32.742021320,1040.0
32.828952840,1053.0
32.915884360,1061.0
33.002815880,1019.0
33.089747400,999.0
33.176678920,986.0
33.263610440,951.0
33.350541960,922.0
33.437473480,945.0
33.524405000,860.0
33.611336520,844.0
33.698268040,854.0
33.785199560,821.0
33.872131080,798.0
33.959062600,814.0
34.045994120,838.0
34.132925640,812.0
34.219857160,826.0
34.306788680,798.0
34.393720200,779.0
34.480651720,810.0
34.567583240,775.0
34.654514760,802.0
34.741446280,720.0
34.828377800,743.0
34.915309320,731.0
35.002240840,724.0
35.089172360,707.0
35.176103880,752.0
35.263035400,704.0
35.349966920,700.0
35.436898440,645.0
35.523829960,625.0
35.610761480,666.0
35.697693000,637.0
35.784624520,629.0
35.871556040,599.0
35.958487560,627.0
36.045419080,621.0
36.132350600,654.0
36.219282120,588.0
36.306213640,610.0
36.393145160,629.0
36.480076680,627.0
36.567008200,620.0
36.653939720,611.0
36.740871240,561.0
36.827802760,586.0
36.914734280,569.0
37.001665800,574.0
37.088597320,605.0
37.175528840,533.0
37.262460360,598.0
37.349391880,529.0
37.436323400,521.0
37.523254920,513.0
37.610186440,564.0
37.697117960,555.0
37.784049480,504.0
37.870981000,530.0
37.957912520,544.0
38.044844040,518.0
38.131775560,510.0
38.218707080,517.0
38.305638600,535.0
38.392570120,507.0
38.479501640,528.0
38.566433160,536.0
38.653364680,529.0
38.740296200,490.0
38.827227720,512.0
38.914159240,498.0
39.001090760,511.0
39.088022280,491.0
39.174953800,457.0
39.261885320,488.0
39.348816840,471.0
39.435748360,469.0
39.522679880,487.0
39.609611400,459.0
39.696542920,471.0
39.783474440,460.0
39.870405960,425.0
39.957337480,449.0
40.044269000,445.0
40.131200520,478.0
40.218132040,458.0
40.305063560,455.0
40.391995080,459.0
40.478926600,400.0
40.565858120,458.0
40.652789640,447.0
40.739721160,493.0
40.826652680,592.0
40.913584200,493.0
41.000515720,446.0
41.087447240,424.0
41.174378760,428.0
41.261310280,418.0
41.348241800,448.0
41.435173320,438.0
41.522104840,405.0
41.609036360,435.0
41.695967880,415.0
41.782899400,413.0
41.869830920,420.0
41.956762440,398.0
42.043693960,398.0
42.130625480,410.0
42.217557000,400.0
42.304488520,423.0
42.391420040,378.0
42.478351560,385.0
42.565283080,385.0
42.652214600,419.0
42.739146120,383.0
42.826077640,422.0
42.913009160,396.0
42.999940680,381.0
43.086872200,385.0
43.173803720,432.0
43.260735240,382.0
43.347666760,450.0
43.434598280,376.0
43.521529800,395.0
43.608461320,419.0
43.695392840,393.0
43.782324360,403.0
43.869255880,444.0
43.956187400,429.0
44.043118920,458.0
44.130050440,397.0
44.216981960,480.0
44.303913480,480.0
44.390845000,459.0
44.477776520,452.0
44.564708040,459.0
44.651639560,499.0
44.738571080,508.0
44.825502600,535.0
44.912434120,570.0
44.999365640,716.0
45.086297160,832.0
45.173228680,1150.0
45.260160200,2016.0
45.347091720,9850.0
45.434023240,30372.0
45.520954760,15465.0
45.607886280,3870.0
45.694817800,1217.0
45.781749320,815.0
45.868680840,607.0
45.955612360,524.0
46.042543880,509.0
46.129475400,475.0
46.216406920,416.0
46.303338440,446.0
46.390269960,416.0
46.477201480,448.0
46.564133000,393.0
46.651064520,410.0
46.737996040,402.0
46.824927560,406.0
46.911859080,384.0
46.998790600,405.0
47.085722120,368.0
47.172653640,399.0
47.259585160,394.0
47.346516680,394.0
47.433448200,379.0
47.520379720,395.0
47.607311240,366.0
47.694242760,371.0
47.781174280,342.0
47.868105800,358.0
47.955037320,322.0
48.041968840,358.0
48.128900360,346.0
48.215831880,349.0
48.302763400,357.0
48.389694920,317.0
48.476626440,373.0
48.563557960,379.0
48.650489480,406.0
48.737421000,377.0
48.824352520,385.0
48.911284040,350.0
48.998215560,367.0
49.085147080,344.0
49.172078600,361.0
49.259010120,377.0
49.345941640,342.0
49.432873160,355.0
49.519804680,335.0
49.606736200,292.0
49.693667720,322.0
49.780599240,280.0
49.867530760,302.0
49.954462280,342.0
50.041393800,300.0
50.128325320,324.0
50.215256840,339.0
50.302188360,326.0
50.389119880,324.0
50.476051400,335.0
50.562982920,350.0
50.649914440,310.0
50.736845960,282.0
50.823777480,286.0
50.910709000,298.0
50.997640520,339.0
51.084572040,294.0
51.171503560,269.0
51.258435080,300.0
51.345366600,289.0
51.432298120,286.0
51.519229640,247.0
51.606161160,272.0
51.693092680,265.0
51.780024200,249.0
51.866955720,284.0
51.953887240,317.0
52.040818760,262.0
52.127750280,301.0
52.214681800,319.0
52.301613320,331.0
52.388544840,345.0
52.475476360,280.0
52.562407880,320.0
52.649339400,305.0
52.736270920,301.0
52.823202440,276.0
52.910133960,306.0
52.997065480,270.0
53.083997000,265.0
53.170928520,296.0
53.257860040,286.0
53.344791560,288.0
53.431723080,274.0
53.518654600,270.0
53.605586120,321.0
53.692517640,295.0
53.779449160,722.0
53.866380680,952.0
53.953312200,723.0
54.040243720,414.0
54.127175240,344.0
54.214106760,318.0
54.301038280,288.0
54.387969800,275.0
54.474901320,251.0
54.561832840,259.0
54.648764360,279.0
54.735695880,279.0
54.822627400,283.0
54.909558920,267.0
54.996490440,271.0
55.083421960,272.0
55.170353480,290.0
55.257285000,290.0
55.344216520,237.0
55.431148040,305.0
55.518079560,275.0
55.605011080,276.0
55.691942600,318.0
55.778874120,293.0
55.865805640,315.0
55.952737160,327.0
56.039668680,356.0
56.126600200,407.0
56.213531720,489.0
56.300463240,833.0
56.387394760,3938.0
56.474326280,5651.0
56.561257800,3521.0
56.648189320,1899.0
56.735120840,543.0
56.822052360,410.0
56.908983880,313.0
56.995915400,279.0
57.082846920,275.0
57.169778440,277.0
57.256709960,244.0
57.343641480,250.0
57.430573000,265.0
57.517504520,281.0
57.604436040,273.0
57.691367560,267.0
57.778299080,265.0
57.865230600,233.0
57.952162120,233.0
58.039093640,233.0
58.126025160,244.0
58.212956680,246.0
58.299888200,225.0
58.386819720,222.0
58.473751240,250.0
58.560682760,232.0
58.647614280,266.0
58.734545800,228.0
58.821477320,247.0
58.908408840,238.0
58.995340360,231.0
59.082271880,257.0
59.169203400,272.0
59.256134920,211.0
59.343066440,233.0
59.429997960,204.0
59.516929480,214.0
59.603861000,247.0
59.690792520,225.0
59.777724040,214.0
59.864655560,205.0
59.951587080,242.0
60.038518600,198.0
60.125450120,244.0
60.212381640,248.0
60.299313160,196.0
60.386244680,195.0
60.473176200,205.0
60.560107720,227.0
60.647039240,242.0
60.733970760,212.0
60.820902280,228.0
60.907833800,230.0
60.994765320,233.0
61.081696840,221.0
61.168628360,226.0
61.255559880,232.0
61.342491400,259.0
61.429422920,220.0
61.516354440,211.0
61.603285960,201.0
61.690217480,229.0
61.777149000,208.0
61.864080520,227.0
61.951012040,223.0
62.037943560,217.0
62.124875080,233.0
62.211806600,205.0
62.298738120,230.0
62.385669640,232.0
62.472601160,212.0
62.559532680,219.0
62.646464200,204.0
62.733395720,229.0
62.820327240,194.0
62.907258760,243.0
62.994190280,223.0
63.081121800,207.0
63.168053320,219.0
63.254984840,225.0
63.341916360,216.0
63.428847880,225.0
63.515779400,216.0
63.602710920,216.0
63.689642440,232.0
63.776573960,250.0
63.863505480,220.0
63.950437000,227.0
64.037368520,243.0
64.124300040,243.0
64.211231560,211.0
64.298163080,225.0
64.385094600,227.0
64.472026120,235.0
64.558957640,227.0
64.645889160,269.0
64.732820680,235.0
64.819752200,244.0
64.906683720,237.0
64.993615240,261.0
65.080546760,234.0
65.167478280,283.0
65.254409800,285.0
65.341341320,214.0
65.428272840,278.0
65.515204360,301.0
65.602135880,279.0
65.689067400,318.0
65.775998920,390.0
65.862930440,466.0
65.949861960,541.0
66.036793480,700.0
66.123725000,2887.0
66.210656520,12604.0
66.297588040,2524.0
66.384519560,6375.0
66.471451080,1404.0
66.558382600,558.0
66.645314120,409.0
66.732245640,346.0
66.819177160,321.0
66.906108680,323.0
66.993040200,334.0
67.079971720,258.0
67.166903240,267.0
67.253834760,281.0
67.340766280,226.0
67.427697800,250.0
67.514629320,241.0
67.601560840,263.0
67.688492360,191.0
67.775423880,244.0
67.862355400,229.0
67.949286920,226.0
68.036218440,207.0
68.123149960,198.0
68.210081480,251.0
68.297013000,208.0
68.383944520,217.0
68.470876040,195.0
68.557807560,236.0
68.644739080,243.0
68.731670600,230.0
68.818602120,193.0
68.905533640,209.0
68.992465160,239.0
69.079396680,224.0
69.166328200,198.0
69.253259720,221.0
69.340191240,216.0
69.427122760,226.0
69.514054280,222.0
69.600985800,194.0
69.687917320,238.0
69.774848840,212.0
69.861780360,214.0
69.948711880,196.0
70.035643400,214.0
70.122574920,230.0
70.209506440,214.0
70.296437960,207.0
70.383369480,213.0
70.470301000,228.0
70.557232520,187.0
70.644164040,209.0
70.731095560,208.0
70.818027080,235.0
70.904958600,215.0
70.991890120,226.0
71.078821640,231.0
71.165753160,221.0
71.252684680,227.0
71.339616200,204.0
71.426547720,217.0
71.513479240,193.0
71.600410760,215.0
71.687342280,235.0
71.774273800,198.0
71.861205320,204.0
71.948136840,211.0
72.035068360,222.0
72.121999880,191.0
72.208931400,231.0
72.295862920,232.0
72.382794440,228.0
72.469725960,249.0
72.556657480,227.0
72.643589000,239.0
72.730520520,239.0
72.817452040,237.0
72.904383560,310.0
72.991315080,450.0
73.078246600,464.0
73.165178120,313.0
73.252109640,421.0
73.339041160,265.0
73.425972680,213.0
73.512904200,238.0
73.599835720,224.0
73.686767240,226.0
73.773698760,207.0
73.860630280,208.0
73.947561800,248.0
74.034493320,208.0
74.121424840,278.0
74.208356360,273.0
74.295287880,263.0
74.382219400,265.0
74.469150920,237.0
74.556082440,234.0
74.643013960,282.0
74.729945480,289.0
74.816877000,326.0
74.903808520,429.0
74.990740040,448.0
75.077671560,628.0
75.164603080,1832.0
75.251534600,6260.0
75.338466120,2155.0
75.425397640,2382.0
75.512329160,2598.0
75.599260680,659.0
75.686192200,404.0
75.773123720,340.0
75.860055240,286.0
75.946986760,272.0
76.033918280,243.0
76.120849800,215.0
76.207781320,205.0
76.294712840,229.0
76.381644360,247.0
76.468575880,229.0
76.555507400,248.0
76.642438920,219.0
76.729370440,219.0
76.816301960,223.0
76.903233480,216.0
76.990165000,218.0
77.077096520,220.0
77.164028040,206.0
77.250959560,178.0
77.337891080,205.0
77.424822600,201.0
77.511754120,192.0
77.598685640,185.0
77.685617160,208.0
77.772548680,183.0
77.859480200,201.0
77.946411720,203.0
78.033343240,195.0
78.120274760,193.0
78.207206280,223.0
78.294137800,183.0
78.381069320,192.0
78.468000840,204.0
78.554932360,187.0
78.641863880,189.0
78.728795400,204.0
78.815726920,210.0
78.902658440,196.0
78.989589960,205.0
79.076521480,211.0
79.163453000,178.0
79.250384520,179.0
79.337316040,184.0
79.424247560,189.0
79.511179080,175.0
79.598110600,217.0
79.685042120,193.0
79.771973640,206.0
79.858905160,208.0
79.945836680,203.0
80.032768200,190.0
80.119699720,187.0
80.206631240,176.0
80.293562760,206.0
80.380494280,187.0
80.467425800,190.0
80.554357320,187.0
80.641288840,196.0
80.728220360,193.0
80.815151880,190.0
80.902083400,218.0
80.989014920,184.0
81.075946440,191.0
81.162877960,177.0
81.249809480,192.0
81.336741000,195.0
81.423672520,190.0
81.510604040,195.0
81.597535560,173.0
81.684467080,193.0
81.771398600,168.0
81.858330120,204.0
81.945261640,192.0
82.032193160,190.0
82.119124680,192.0
82.206056200,196.0
82.292987720,176.0
82.379919240,176.0
82.466850760,181.0
82.553782280,205.0
82.640713800,215.0
82.727645320,192.0
82.814576840,207.0
82.901508360,212.0
82.988439880,208.0
83.075371400,188.0
83.162302920,219.0
83.249234440,180.0
83.336165960,207.0
83.423097480,243.0
83.510029000,248.0
83.596960520,265.0
83.683892040,308.0
83.770823560,416.0
83.857755080,1033.0
83.944686600,3409.0
84.031618120,1542.0
84.118549640,924.0
84.205481160,1886.0
84.292412680,842.0
84.379344200,378.0
84.466275720,319.0
84.553207240,227.0
84.640138760,201.0
84.727070280,214.0
84.814001800,203.0
84.900933320,201.0
84.987864840,218.0
85.074796360,181.0
85.161727880,173.0
85.248659400,176.0
85.335590920,190.0
85.422522440,181.0
85.509453960,166.0
85.596385480,175.0
85.683317000,163.0
85.770248520,187.0
85.857180040,168.0
85.944111560,189.0
86.031043080,191.0
86.117974600,204.0
86.204906120,158.0
86.291837640,178.0
86.378769160,163.0
86.465700680,169.0
86.552632200,148.0
86.639563720,163.0
86.726495240,168.0
86.813426760,168.0
86.900358280,157.0
86.987289800,155.0
87.074221320,163.0
87.161152840,143.0
87.248084360,158.0
87.335015880,164.0
87.421947400,157.0
87.508878920,145.0
87.595810440,182.0
87.682741960,176.0
87.769673480,152.0
87.856605000,179.0
87.943536520,175.0
88.030468040,156.0
88.117399560,168.0
88.204331080,193.0
88.291262600,171.0
88.378194120,165.0
88.465125640,180.0
88.552057160,179.0
88.638988680,179.0
88.725920200,175.0
88.812851720,162.0
88.899783240,176.0
88.986714760,147.0
89.073646280,153.0
89.160577800,174.0
89.247509320,169.0
89.334440840,171.0
89.421372360,153.0
89.508303880,180.0
89.595235400,176.0
89.682166920,169.0
89.769098440,184.0
89.856029960,153.0
89.942961480,157.0
90.029893000,161.0
90.116824520,158.0
90.203756040,195.0
90.290687560,297.0
90.377619080,674.0
90.464550600,343.0
90.551482120,243.0
90.638413640,380.0
90.725345160,275.0
90.812276680,202.0
90.899208200,164.0
90.986139720,180.0
91.073071240,175.0
91.160002760,160.0
91.246934280,181.0
91.333865800,156.0
91.420797320,167.0
91.507728840,174.0
91.594660360,142.0
91.681591880,173.0
91.768523400,177.0
91.855454920,148.0
91.942386440,183.0
92.029317960,185.0
92.116249480,154.0
92.203181000,154.0
92.290112520,147.0
92.377044040,152.0
92.463975560,171.0
92.550907080,146.0
92.637838600,140.0
92.724770120,157.0
92.811701640,164.0
92.898633160,171.0
92.985564680,170.0
93.072496200,182.0
93.159427720,150.0
93.246359240,165.0
93.333290760,154.0
93.420222280,151.0
93.507153800,143.0
93.594085320,158.0
93.681016840,154.0
93.767948360,177.0
93.854879880,153.0
93.941811400,152.0
94.028742920,152.0
94.115674440,140.0
94.202605960,170.0
94.289537480,148.0
94.376469000,158.0
94.463400520,123.0
94.550332040,139.0
94.637263560,152.0
94.724195080,151.0
94.811126600,153.0
94.898058120,158.0
94.984989640,127.0
95.071921160,144.0
95.158852680,188.0
95.245784200,140.0
95.332715720,124.0
95.419647240,152.0
95.506578760,185.0
95.593510280,149.0
95.680441800,158.0
95.767373320,165.0
95.854304840,157.0
95.941236360,145.0
96.028167880,134.0
96.115099400,141.0
96.202030920,157.0
96.288962440,160.0
96.375893960,160.0
96.462825480,150.0
96.549757000,145.0
96.636688520,164.0
96.723620040,137.0
96.810551560,158.0
96.897483080,147.0
96.984414600,148.0
97.071346120,133.0
97.158277640,155.0
97.245209160,186.0
97.332140680,172.0
97.419072200,172.0
97.506003720,168.0
97.592935240,162.0
97.679866760,151.0
97.766798280,168.0
97.853729800,130.0
97.940661320,169.0
98.027592840,151.0
98.114524360,161.0
98.201455880,135.0
98.288387400,140.0
98.375318920,158.0
98.462250440,163.0
98.549181960,158.0
98.636113480,152.0
98.723045000,145.0
98.809976520,143.0
98.896908040,166.0
98.983839560,163.0
99.070771080,161.0
99.157702600,127.0
99.244634120,157.0
99.331565640,182.0
99.418497160,164.0
99.505428680,158.0
99.592360200,161.0
99.679291720,180.0
99.766223240,157.0
99.853154760,181.0
99.940086280,152.0
100.027017800,158.0
100.113949320,168.0
100.200880840,177.0
100.287812360,202.0
100.374743880,204.0
100.461675400,194.0
100.548606920,185.0
100.635538440,200.0
100.722469960,199.0
100.809401480,212.0
100.896333000,240.0
100.983264520,312.0
101.070196040,809.0
101.157127560,1643.0
101.244059080,656.0
101.330990600,388.0
101.417922120,576.0
101.504853640,875.0
101.591785160,410.0
101.678716680,230.0
101.765648200,241.0
101.852579720,181.0
101.939511240,201.0
102.026442760,165.0
102.113374280,194.0
102.200305800,180.0
102.287237320,183.0
102.374168840,179.0
102.461100360,187.0
102.548031880,173.0
102.634963400,197.0
102.721894920,160.0
102.808826440,181.0
102.895757960,182.0
102.982689480,181.0
103.069621000,210.0
103.156552520,176.0
103.243484040,187.0
103.330415560,154.0
103.417347080,176.0
103.504278600,177.0
103.591210120,169.0
103.678141640,160.0
103.765073160,169.0
103.852004680,207.0
103.938936200,163.0
104.025867720,182.0
104.112799240,179.0
104.199730760,175.0
104.286662280,172.0
104.373593800,167.0
104.460525320,155.0
104.547456840,147.0
104.634388360,154.0
104.721319880,184.0
104.808251400,164.0
104.895182920,171.0
104.982114440,164.0
105.069045960,186.0
105.155977480,202.0
105.242909000,194.0
105.329840520,166.0
105.416772040,178.0
105.503703560,202.0
105.590635080,187.0
105.677566600,206.0
105.764498120,187.0
105.851429640,202.0
105.938361160,182.0
106.025292680,207.0
106.112224200,163.0
106.199155720,183.0
106.286087240,169.0
106.373018760,179.0
106.459950280,193.0
106.546881800,204.0
106.633813320,196.0
106.720744840,212.0
106.807676360,169.0
106.894607880,170.0
106.981539400,196.0
107.068470920,183.0
107.155402440,181.0
107.242333960,169.0
107.329265480,192.0
107.416197000,232.0
107.503128520,185.0
107.590060040,228.0
107.676991560,312.0
107.763923080,520.0
107.850854600,336.0
107.937786120,246.0
108.024717640,286.0
108.111649160,342.0
108.198580680,322.0
108.285512200,221.0
108.372443720,225.0
108.459375240,180.0
108.546306760,215.0
108.633238280,200.0
108.720169800,202.0
108.807101320,205.0
108.894032840,215.0
108.980964360,217.0
109.067895880,218.0
109.154827400,216.0
109.241758920,244.0
109.328690440,230.0
109.415621960,262.0
109.502553480,245.0
109.589485000,279.0
109.676416520,290.0
109.763348040,408.0
109.850279560,556.0
109.937211080,1293.0
110.002409720,2967.0