File: Datos_proyecto_final/NaCl_TT_500/NaCl_TT_500.csv
[Measurement conditions]
Sample identification,NaCl_TT_500
Comment,
Anode material,Cu
K-Alpha1 wavelength,1.5405980
K-Alpha2 wavelength,1.5444260
Ratio K-Alpha2/K-Alpha1,0.500
Divergence slit,Fixed,0.76mm
Monochromator used,NO
Generator voltage, 40
Tube current,  8
File date and time,26/Jul./2022 03:28
Unit cell,
h k l, 0 0 0
Scan axis,Gonio
Scan range,5.000000000,110.013276160
Scan step size,0.0217329
No. of points, 4832
Scan type,CONTINUOUS
Time per step,49.470
[Scan points]
Angle,Intensity
5.010866440,3977.0
5.097797960,3792.0
5.184729480,3671.0
5.271661000,3330.0
5.358592520,3316.0
5.445524040,3114.0
5.532455560,3069.0
5.619387080,2971.0
5.706318600,2877.0
5.793250120,2776.0
5.880181640,2727.0
5.967113160,2614.0
6.054044680,2571.0
6.140976200,2480.0
6.227907720,2457.0
6.314839240,2476.0
6.401770760,2530.0
6.488702280,2332.0
6.575633800,2396.0
6.662565320,2483.0
6.749496840,2346.0
6.836428360,2318.0
6.923359880,2243.0
7.010291400,2366.0
7.097222920,2294.0
7.184154440,2268.0
7.271085960,2268.0
7.358017480,2246.0
7.444949000,2429.0
7.531880520,2280.0
7.618812040,2268.0
7.705743560,2286.0
7.792675080,2246.0
7.879606600,2266.0
7.966538120,2232.0
8.053469640,2141.0
8.140401160,2316.0
8.227332680,2259.0
8.314264200,2293.0
8.401195720,2153.0
8.488127240,2224.0
8.575058760,2204.0
8.661990280,2301.0
8.748921800,2182.0
8.835853320,2255.0
8.922784840,2222.0
9.009716360,2216.0
9.096647880,2291.0
9.183579400,2211.0
9.270510920,2290.0
9.357442440,2326.0
9.444373960,2196.0
9.531305480,2258.0
9.618237000,2257.0
9.705168520,2279.0
9.792100040,2202.0
9.879031560,2197.0
9.965963080,2209.0
10.052894600,2214.0
10.139826120,2198.0
10.226757640,2244.0
10.313689160,2290.0
10.400620680,2194.0
10.487552200,2246.0
10.574483720,2197.0
10.661415240,2371.0
10.748346760,2431.0
10.835278280,2186.0
10.922209800,2238.0
11.009141320,2288.0
11.096072840,2194.0
11.183004360,2211.0
11.269935880,2242.0
11.356867400,2255.0
11.443798920,2251.0
11.530730440,2265.0
11.617661960,2188.0
11.704593480,2257.0
11.791525000,2217.0
11.878456520,2273.0
11.965388040,2189.0
12.052319560,2327.0
12.139251080,2163.0
12.226182600,2217.0
12.313114120,2168.0
12.400045640,2107.0
12.486977160,2167.0
12.573908680,2232.0
12.660840200,2148.0
12.747771720,2196.0
12.834703240,2156.0
12.921634760,2058.0
13.008566280,2149.0
13.095497800,2115.0
13.182429320,2100.0
13.269360840,2131.0
13.356292360,2038.0
13.443223880,1940.0
13.530155400,2073.0
13.617086920,2110.0
13.704018440,2030.0
13.790949960,1992.0
13.877881480,1992.0
13.964813000,1989.0
14.051744520,1990.0
14.138676040,1906.0
14.225607560,1909.0
14.312539080,1981.0
14.399470600,1984.0
14.486402120,1908.0
14.573333640,1993.0
14.660265160,1973.0
14.747196680,1892.0
14.834128200,1929.0
14.921059720,1961.0
15.007991240,1975.0
15.094922760,1845.0
15.181854280,1844.0
15.268785800,1815.0
15.355717320,1826.0
15.442648840,1848.0
15.529580360,1840.0
15.616511880,1827.0
15.703443400,1809.0
15.790374920,1799.0
15.877306440,1780.0
15.964237960,1761.0
16.051169480,1809.0
16.138101000,1795.0
16.225032520,1695.0
16.311964040,1636.0
16.398895560,1653.0
16.485827080,1646.0
16.572758600,1681.0
16.659690120,1705.0
16.746621640,1508.0
16.833553160,1635.0
16.920484680,1612.0
17.007416200,1562.0
17.094347720,1646.0
17.181279240,1582.0
17.268210760,1610.0
17.355142280,1610.0
17.442073800,1560.0
17.529005320,1658.0
17.615936840,1573.0
17.702868360,1620.0
17.789799880,1476.0
17.876731400,1494.0
17.963662920,1470.0
18.050594440,1454.0
18.137525960,1398.0
18.224457480,1408.0
18.311389000,1400.0
18.398320520,1497.0
18.485252040,1410.0
18.572183560,1443.0
18.659115080,1428.0
18.746046600,1418.0
18.832978120,1409.0
18.919909640,1422.0
19.006841160,1324.0
19.093772680,1322.0
19.180704200,1393.0
19.267635720,1387.0
19.354567240,1377.0
19.441498760,1375.0
19.528430280,1314.0
19.615361800,1279.0
19.702293320,1335.0
19.789224840,1330.0
19.876156360,1318.0
19.963087880,1323.0
20.050019400,1256.0
20.136950920,1335.0
20.223882440,1218.0
20.310813960,1257.0
20.397745480,1200.0
20.484677000,1226.0
20.571608520,1239.0
20.658540040,1252.0
20.745471560,1241.0
20.832403080,1228.0
20.919334600,1185.0
21.006266120,1175.0
21.093197640,1191.0
21.180129160,1205.0
21.267060680,1196.0
21.353992200,1186.0
21.440923720,1111.0
21.527855240,1149.0
21.614786760,1166.0
21.701718280,1124.0
21.788649800,1127.0
21.875581320,1095.0
21.962512840,1116.0
22.049444360,1107.0
22.136375880,1147.0
22.223307400,1079.0
22.310238920,1048.0
22.397170440,1080.0
22.484101960,1068.0
22.571033480,1071.0
22.657965000,1032.0
22.744896520,998.0
22.831828040,1031.0
22.918759560,1027.0
23.005691080,1033.0
23.092622600,1001.0
23.179554120,1017.0
23.266485640,1031.0
23.353417160,1012.0
23.440348680,967.0
23.527280200,964.0
23.614211720,972.0
23.701143240,929.0
23.788074760,944.0
23.875006280,962.0
23.961937800,922.0
24.048869320,916.0
24.135800840,882.0
24.222732360,927.0
24.309663880,889.0
24.396595400,824.0
24.483526920,917.0
24.570458440,910.0
24.657389960,892.0
24.744321480,855.0
24.831253000,904.0
24.918184520,902.0
25.005116040,863.0
25.092047560,892.0
25.178979080,903.0
25.265910600,972.0
25.352842120,1224.0
25.439773640,2045.0
25.526705160,2054.0
25.613636680,1033.0
25.700568200,828.0
25.787499720,858.0
25.874431240,795.0
25.961362760,883.0
26.048294280,828.0
26.135225800,821.0
26.222157320,758.0
26.309088840,796.0
26.396020360,826.0
26.482951880,799.0
26.569883400,790.0
26.656814920,839.0
26.743746440,803.0
26.830677960,757.0
26.917609480,844.0
27.004541000,817.0
27.091472520,871.0
27.178404040,957.0
27.265335560,1437.0
27.352267080,3735.0
27.439198600,3538.0
27.526130120,1254.0
27.613061640,850.0
27.699993160,775.0
27.786924680,760.0
27.873856200,766.0
27.960787720,721.0
28.047719240,724.0
28.134650760,703.0
28.221582280,734.0
28.308513800,698.0
28.395445320,739.0
28.482376840,818.0
28.569308360,1208.0
28.656239880,994.0
28.743171400,783.0
28.830102920,725.0
28.917034440,729.0
29.003965960,729.0
29.090897480,725.0
29.177829000,666.0
29.264760520,743.0
29.351692040,680.0
29.438623560,699.0
29.525555080,651.0
29.612486600,741.0
29.699418120,666.0
29.786349640,677.0
29.873281160,670.0
29.960212680,710.0
30.047144200,740.0
30.134075720,696.0
30.221007240,767.0
30.307938760,745.0
30.394870280,745.0
30.481801800,793.0
30.568733320,837.0
30.655664840,1135.0
30.742596360,1217.0
30.829527880,1229.0
30.916459400,1320.0
31.003390920,1264.0
31.090322440,1354.0
31.177253960,1599.0
31.264185480,2207.0
31.351117000,3042.0
31.438048520,4012.0
31.524980040,6885.0
31.611911560,24865.0
31.698843080,130912.0
31.785774600,108754.0
31.872706120,23294.0
31.959637640,5467.0
32.046569160,3522.0
32.133500680,2174.0
32.220432200,1541.0
32.307363720,1326.0
32.394295240,1211.0
32.481226760,1154.0
32.568158280,1088.0
32.655089800,1096.0
32.742021320,1049.0
32.828952840,1002.0
32.915884360,905.0
33.002815880,918.0
33.089747400,927.0
33.176678920,874.0
33.263610440,861.0
33.350541960,849.0
33.437473480,857.0
33.524405000,837.0
33.611336520,836.0
33.698268040,758.0
33.785199560,839.0
33.872131080,791.0
33.959062600,778.0
34.045994120,761.0
34.132925640,797.0
34.219857160,766.0
34.306788680,691.0
34.393720200,714.0
34.480651720,768.0
34.567583240,735.0
34.654514760,771.0
34.741446280,751.0
34.828377800,738.0
34.915309320,756.0
35.002240840,699.0
35.089172360,697.0
35.176103880,719.0
35.263035400,686.0
35.349966920,602.0
35.436898440,638.0
35.523829960,610.0
35.610761480,649.0
35.697693000,624.0
35.784624520,622.0
35.871556040,601.0
35.958487560,614.0
36.045419080,632.0
36.132350600,637.0
36.219282120,636.0
36.306213640,647.0
36.393145160,639.0
36.480076680,598.0
36.567008200,540.0
36.653939720,539.0
36.740871240,574.0
36.827802760,568.0
36.914734280,525.0
37.001665800,516.0
37.088597320,549.0
37.175528840,550.0
37.262460360,526.0
37.349391880,531.0
37.436323400,528.0
37.523254920,519.0
37.610186440,503.0
37.697117960,550.0
37.784049480,484.0
37.870981000,510.0
37.957912520,482.0
38.044844040,521.0
38.131775560,452.0
38.218707080,508.0
38.305638600,509.0
38.392570120,491.0
38.479501640,461.0
38.566433160,548.0
38.653364680,702.0
38.740296200,529.0
38.827227720,557.0
38.914159240,492.0
39.001090760,464.0
39.088022280,450.0
39.174953800,454.0
39.261885320,468.0
39.348816840,490.0
39.435748360,452.0
39.522679880,431.0
39.609611400,443.0
39.696542920,442.0
39.783474440,426.0
39.870405960,452.0
39.957337480,471.0
40.044269000,484.0
40.131200520,462.0
40.218132040,429.0
40.305063560,433.0
40.391995080,401.0
40.478926600,467.0
40.565858120,436.0
40.652789640,431.0
40.739721160,479.0
40.826652680,652.0
40.913584200,633.0
41.000515720,491.0
41.087447240,464.0
41.174378760,410.0
41.261310280,399.0
41.348241800,504.0
41.435173320,497.0
41.522104840,480.0
41.609036360,427.0
41.695967880,461.0
41.782899400,416.0
41.869830920,405.0
41.956762440,378.0
42.043693960,423.0
42.130625480,403.0
42.217557000,434.0
42.304488520,357.0
42.391420040,377.0
42.478351560,413.0
42.565283080,343.0
42.652214600,399.0
42.739146120,371.0
42.826077640,425.0
42.913009160,387.0
42.999940680,395.0
43.086872200,426.0
43.173803720,373.0
43.260735240,387.0
43.347666760,450.0
43.434598280,397.0
43.521529800,403.0
43.608461320,418.0
43.695392840,372.0
43.782324360,404.0
43.869255880,495.0
43.956187400,487.0
44.043118920,475.0
44.130050440,411.0
44.216981960,455.0
44.303913480,451.0
44.390845000,455.0
44.477776520,439.0
44.564708040,522.0
44.651639560,468.0
44.738571080,478.0
44.825502600,533.0
44.912434120,581.0
44.999365640,701.0
45.086297160,898.0
45.173228680,1275.0
45.260160200,1939.0
45.347091720,5469.0
45.434023240,24865.0
45.520954760,18399.0
45.607886280,13679.0
45.694817800,3021.0
45.781749320,1327.0
45.868680840,819.0
45.955612360,672.0
46.042543880,528.0
46.129475400,518.0
46.216406920,527.0
46.303338440,469.0
46.390269960,414.0
46.477201480,431.0
46.564133000,440.0
46.651064520,402.0
46.737996040,472.0
46.824927560,406.0
46.911859080,425.0
46.998790600,436.0
47.085722120,379.0
47.172653640,423.0
47.259585160,409.0
47.346516680,396.0
47.433448200,394.0
47.520379720,407.0
47.607311240,377.0
47.694242760,353.0
47.781174280,358.0
47.868105800,347.0
47.955037320,326.0
48.041968840,365.0
48.128900360,372.0
48.215831880,381.0
48.302763400,334.0
48.389694920,373.0
48.476626440,364.0
48.563557960,374.0
48.650489480,432.0
48.737421000,469.0
48.824352520,447.0
48.911284040,359.0
48.998215560,311.0
49.085147080,375.0
49.172078600,346.0
49.259010120,368.0
49.345941640,336.0
49.432873160,324.0
49.519804680,314.0
49.606736200,308.0
49.693667720,340.0
49.780599240,332.0
49.867530760,301.0
49.954462280,315.0
50.041393800,303.0
50.128325320,336.0
50.215256840,332.0
50.302188360,313.0
50.389119880,287.0
50.476051400,285.0
50.562982920,304.0
50.649914440,320.0
50.736845960,287.0
50.823777480,317.0
50.910709000,317.0
50.997640520,312.0
51.084572040,294.0
51.171503560,312.0
51.258435080,276.0
51.345366600,279.0
51.432298120,282.0
51.519229640,271.0
51.606161160,308.0
51.693092680,299.0
51.780024200,290.0
51.866955720,327.0
51.953887240,268.0
52.040818760,271.0
52.127750280,281.0
52.214681800,353.0
52.301613320,372.0
52.388544840,311.0
52.475476360,341.0
52.562407880,299.0
52.649339400,315.0
52.736270920,276.0
52.823202440,276.0
52.910133960,273.0
52.997065480,246.0
53.083997000,295.0
53.170928520,267.0
53.257860040,285.0
53.344791560,270.0
53.431723080,289.0
53.518654600,266.0
53.605586120,304.0
53.692517640,314.0
53.779449160,476.0
53.866380680,1029.0
53.953312200,720.0
54.040243720,674.0
54.127175240,379.0
54.214106760,318.0
54.301038280,299.0
54.387969800,279.0
54.474901320,293.0
54.561832840,289.0
54.648764360,291.0
54.735695880,260.0
54.822627400,297.0
54.909558920,291.0
54.996490440,271.0
55.083421960,265.0
55.170353480,275.0
55.257285000,285.0
55.344216520,299.0
55.431148040,270.0
55.518079560,303.0
55.605011080,291.0
55.691942600,380.0
55.778874120,366.0
55.865805640,336.0
55.952737160,362.0
56.039668680,376.0
56.126600200,433.0
56.213531720,530.0
56.300463240,802.0
56.387394760,2257.0
56.474326280,6038.0
56.561257800,3402.0
56.648189320,3246.0
56.735120840,1142.0
56.822052360,555.0
56.908983880,387.0
56.995915400,359.0
57.082846920,309.0
57.169778440,282.0
57.256709960,302.0
57.343641480,270.0
57.430573000,237.0
57.517504520,269.0
57.604436040,249.0
57.691367560,245.0
57.778299080,283.0
57.865230600,240.0
57.952162120,278.0
58.039093640,246.0
58.126025160,238.0
58.212956680,229.0
58.299888200,217.0
58.386819720,233.0
58.473751240,227.0
58.560682760,215.0
58.647614280,246.0
58.734545800,229.0
58.821477320,239.0
58.908408840,256.0
58.995340360,265.0
59.082271880,286.0
59.169203400,268.0
59.256134920,266.0
59.343066440,236.0
59.429997960,224.0
59.516929480,240.0
59.603861000,241.0
59.690792520,236.0
59.777724040,228.0
59.864655560,208.0
59.951587080,233.0
60.038518600,215.0
60.125450120,192.0
60.212381640,214.0
60.299313160,205.0
60.386244680,226.0
60.473176200,213.0
60.560107720,230.0
60.647039240,249.0
60.733970760,215.0
60.820902280,204.0
60.907833800,244.0
60.994765320,225.0
61.081696840,214.0
61.168628360,223.0
61.255559880,220.0
61.342491400,227.0
61.429422920,218.0
61.516354440,223.0
61.603285960,213.0
61.690217480,212.0
61.777149000,210.0
61.864080520,204.0
61.951012040,196.0
62.037943560,221.0
62.124875080,196.0
62.211806600,211.0
62.298738120,286.0
62.385669640,245.0
62.472601160,235.0
62.559532680,226.0
62.646464200,216.0
62.733395720,212.0
62.820327240,210.0
62.907258760,205.0
62.994190280,215.0
63.081121800,232.0
63.168053320,223.0
63.254984840,248.0
63.341916360,207.0
63.428847880,216.0
63.515779400,196.0
63.602710920,202.0
63.689642440,225.0
63.776573960,200.0
63.863505480,226.0
63.950437000,220.0
64.037368520,240.0
64.124300040,236.0
64.211231560,257.0
64.298163080,208.0
64.385094600,233.0
64.472026120,238.0
64.558957640,214.0
64.645889160,247.0
64.732820680,210.0
64.819752200,227.0
64.906683720,238.0
64.993615240,234.0
65.080546760,270.0
65.167478280,226.0
65.254409800,211.0
65.341341320,236.0
65.428272840,247.0
65.515204360,268.0
65.602135880,312.0
65.689067400,292.0
65.775998920,386.0
65.862930440,443.0
65.949861960,507.0
66.036793480,691.0
66.123725000,1579.0
66.210656520,6529.0
66.297588040,4623.0
66.384519560,3622.0
66.471451080,2960.0
66.558382600,849.0
66.645314120,486.0
66.732245640,342.0
66.819177160,326.0
66.906108680,275.0
66.993040200,290.0
67.079971720,242.0
67.166903240,257.0
67.253834760,258.0
67.340766280,243.0
67.427697800,232.0
67.514629320,259.0
67.601560840,219.0
67.688492360,241.0
67.775423880,228.0
67.862355400,214.0
67.949286920,229.0
68.036218440,224.0
68.123149960,235.0
68.210081480,214.0
68.297013000,191.0
68.383944520,219.0
68.470876040,246.0
68.557807560,215.0
68.644739080,234.0
68.731670600,222.0
68.818602120,199.0
68.905533640,224.0
68.992465160,214.0
69.079396680,221.0
69.166328200,205.0
69.253259720,215.0
69.340191240,188.0
69.427122760,191.0
69.514054280,211.0
69.600985800,189.0
69.687917320,208.0
69.774848840,221.0
69.861780360,222.0
69.948711880,192.0
70.035643400,234.0
70.122574920,225.0
70.209506440,226.0
70.296437960,202.0
70.383369480,190.0
70.470301000,213.0
70.557232520,203.0
70.644164040,196.0
70.731095560,202.0
70.818027080,210.0
70.904958600,213.0
70.991890120,207.0
71.078821640,209.0
71.165753160,197.0
71.252684680,233.0
71.339616200,242.0
71.426547720,196.0
71.513479240,228.0
71.600410760,218.0
71.687342280,211.0
71.774273800,196.0
71.861205320,245.0
71.948136840,200.0
72.035068360,188.0
72.121999880,208.0
72.208931400,192.0
72.295862920,224.0
72.382794440,232.0
72.469725960,233.0
72.556657480,226.0
72.643589000,246.0
72.730520520,225.0
72.817452040,275.0
72.904383560,256.0
72.991315080,420.0
73.078246600,503.0
73.165178120,344.0
73.252109640,373.0
73.339041160,312.0
73.425972680,241.0
73.512904200,258.0
73.599835720,205.0
73.686767240,235.0
73.773698760,224.0
73.860630280,260.0
73.947561800,220.0
74.034493320,227.0
74.121424840,228.0
74.208356360,332.0
74.295287880,292.0
74.382219400,281.0
74.469150920,290.0
74.556082440,275.0
74.643013960,311.0
74.729945480,305.0
74.816877000,378.0
74.903808520,438.0
74.990740040,516.0
75.077671560,729.0
75.164603080,1584.0
75.251534600,4657.0
75.338466120,4437.0
75.425397640,2539.0
75.512329160,3372.0
75.599260680,1592.0
75.686192200,769.0
75.773123720,462.0
75.860055240,338.0
75.946986760,311.0
76.033918280,296.0
76.120849800,282.0
76.207781320,248.0
76.294712840,257.0
76.381644360,220.0
76.468575880,219.0
76.555507400,232.0
76.642438920,236.0
76.729370440,232.0
76.816301960,236.0
76.903233480,224.0
76.990165000,204.0
77.077096520,235.0
77.164028040,211.0
77.250959560,244.0
77.337891080,241.0
77.424822600,209.0
77.511754120,243.0
77.598685640,180.0
77.685617160,203.0
77.772548680,197.0
77.859480200,209.0
77.946411720,202.0
78.033343240,207.0
78.120274760,220.0
78.207206280,197.0
78.294137800,168.0
78.381069320,196.0
78.468000840,212.0
78.554932360,196.0
78.641863880,238.0
78.728795400,235.0
78.815726920,211.0
78.902658440,233.0
78.989589960,182.0
79.076521480,196.0
79.163453000,194.0
79.250384520,178.0
79.337316040,193.0
79.424247560,217.0
79.511179080,198.0
79.598110600,181.0
79.685042120,182.0
79.771973640,207.0
79.858905160,206.0
79.945836680,206.0
80.032768200,194.0
80.119699720,195.0
80.206631240,165.0
80.293562760,175.0
80.380494280,196.0
80.467425800,181.0
80.554357320,210.0
80.641288840,194.0
80.728220360,199.0
80.815151880,184.0
80.902083400,204.0
80.989014920,194.0
81.075946440,184.0
81.162877960,203.0
81.249809480,195.0
81.336741000,195.0
81.423672520,172.0
81.510604040,192.0
81.597535560,207.0
81.684467080,197.0
81.771398600,200.0
81.858330120,201.0
81.945261640,187.0
82.032193160,166.0
82.119124680,182.0
82.206056200,198.0
82.292987720,177.0
82.379919240,219.0
82.466850760,199.0
82.553782280,206.0
82.640713800,222.0
82.727645320,222.0
82.814576840,234.0
82.901508360,235.0
82.988439880,237.0
83.075371400,240.0
83.162302920,221.0
83.249234440,224.0
83.336165960,219.0
83.423097480,235.0
83.510029000,259.0
83.596960520,320.0
83.683892040,364.0
83.770823560,496.0
83.857755080,945.0
83.944686600,2195.0
84.031618120,2212.0
84.118549640,1312.0
84.205481160,1518.0
84.292412680,1232.0
84.379344200,642.0
84.466275720,425.0
84.553207240,307.0
84.640138760,273.0
84.727070280,237.0
84.814001800,193.0
84.900933320,212.0
84.987864840,194.0
85.074796360,180.0
85.161727880,179.0
85.248659400,178.0
85.335590920,184.0
85.422522440,175.0
85.509453960,205.0
85.596385480,161.0
85.683317000,205.0
85.770248520,186.0
85.857180040,163.0
85.944111560,180.0
86.031043080,184.0
86.117974600,205.0
86.204906120,157.0
86.291837640,174.0
86.378769160,170.0
86.465700680,176.0
86.552632200,176.0
86.639563720,182.0
86.726495240,190.0
86.813426760,170.0
86.900358280,151.0
86.987289800,187.0
87.074221320,151.0
87.161152840,165.0
87.248084360,172.0
87.335015880,153.0
87.421947400,155.0
87.508878920,169.0
87.595810440,168.0
87.682741960,171.0
87.769673480,157.0
87.856605000,172.0
87.943536520,159.0
88.030468040,192.0
88.117399560,191.0
88.204331080,185.0
88.291262600,202.0
88.378194120,192.0
88.465125640,196.0
88.552057160,195.0
88.638988680,180.0
88.725920200,171.0
88.812851720,188.0
88.899783240,192.0
88.986714760,164.0
89.073646280,166.0
89.160577800,188.0
89.247509320,133.0
89.334440840,175.0
89.421372360,148.0
89.508303880,164.0
89.595235400,148.0
89.682166920,138.0
89.769098440,172.0
89.856029960,173.0
89.942961480,178.0
90.029893000,161.0
90.116824520,151.0
90.203756040,181.0
90.290687560,248.0
90.377619080,406.0
90.464550600,383.0
90.551482120,275.0
90.638413640,287.0
90.725345160,312.0
90.812276680,210.0
90.899208200,178.0
90.986139720,177.0
91.073071240,180.0
91.160002760,155.0
91.246934280,175.0
91.333865800,149.0
91.420797320,177.0
91.507728840,161.0
91.594660360,175.0
91.681591880,160.0
91.768523400,153.0
91.855454920,175.0
91.942386440,157.0
92.029317960,158.0
92.116249480,132.0
92.203181000,184.0
92.290112520,157.0
92.377044040,163.0
92.463975560,154.0
92.550907080,132.0
92.637838600,163.0
92.724770120,139.0
92.811701640,147.0
92.898633160,151.0
92.985564680,134.0
93.072496200,157.0
93.159427720,149.0
93.246359240,157.0
93.333290760,140.0
93.420222280,173.0
93.507153800,131.0
93.594085320,166.0
93.681016840,165.0
93.767948360,157.0
93.854879880,138.0
93.941811400,155.0
94.028742920,148.0
94.115674440,147.0
94.202605960,153.0
94.289537480,164.0
94.376469000,170.0
94.463400520,141.0
94.550332040,162.0
94.637263560,127.0
94.724195080,181.0
94.811126600,192.0
94.898058120,153.0
94.984989640,146.0
95.071921160,166.0
95.158852680,171.0
95.245784200,159.0
95.332715720,149.0
95.419647240,138.0
95.506578760,159.0
95.593510280,158.0
95.680441800,152.0
95.767373320,159.0
95.854304840,161.0
95.941236360,165.0
96.028167880,151.0
96.115099400,176.0
96.202030920,164.0
96.288962440,161.0
96.375893960,146.0
96.462825480,138.0
96.549757000,157.0
96.636688520,184.0
96.723620040,166.0
96.810551560,155.0
96.897483080,150.0
96.984414600,172.0
97.071346120,158.0
97.158277640,146.0
97.245209160,159.0
97.332140680,157.0
97.419072200,175.0
97.506003720,148.0
97.592935240,125.0
97.679866760,145.0
97.766798280,155.0
97.853729800,152.0
97.940661320,152.0
98.027592840,154.0
98.114524360,127.0
98.201455880,160.0
98.288387400,186.0
98.375318920,162.0
98.462250440,192.0
98.549181960,148.0
98.636113480,150.0
98.723045000,161.0
98.809976520,172.0
98.896908040,144.0
98.983839560,178.0
99.070771080,129.0
99.157702600,157.0
99.244634120,151.0
99.331565640,153.0
99.418497160,166.0
99.505428680,170.0
99.592360200,174.0
99.679291720,170.0
99.766223240,182.0
99.853154760,188.0
99.940086280,178.0
100.027017800,171.0
100.113949320,140.0
100.200880840,151.0
100.287812360,154.0
100.374743880,154.0
100.461675400,176.0
100.548606920,189.0
100.635538440,212.0
100.722469960,199.0
100.809401480,245.0
100.896333000,268.0
100.983264520,364.0
101.070196040,681.0
101.157127560,1029.0
101.244059080,853.0
101.330990600,493.0
101.417922120,542.0
101.504853640,704.0
101.591785160,469.0
101.678716680,334.0
101.765648200,270.0
101.852579720,216.0
101.939511240,217.0
102.026442760,199.0
102.113374280,177.0
102.200305800,203.0
102.287237320,176.0
102.374168840,166.0
102.461100360,186.0
102.548031880,182.0
102.634963400,190.0
102.721894920,147.0
102.808826440,188.0
102.895757960,163.0
102.982689480,158.0
103.069621000,154.0
103.156552520,186.0
103.243484040,141.0
103.330415560,181.0
103.417347080,161.0
103.504278600,173.0
103.591210120,177.0
103.678141640,181.0
103.765073160,179.0
103.852004680,179.0
103.938936200,168.0
104.025867720,151.0
104.112799240,168.0
104.199730760,159.0
104.286662280,187.0
104.373593800,184.0
104.460525320,155.0
104.547456840,184.0
104.634388360,206.0
104.721319880,182.0
104.808251400,160.0
104.895182920,184.0
104.982114440,189.0
105.069045960,166.0
105.155977480,207.0
105.242909000,188.0
105.329840520,183.0
105.416772040,176.0
105.503703560,185.0
105.590635080,202.0
105.677566600,195.0
105.764498120,176.0
105.851429640,204.0
105.938361160,189.0
106.025292680,179.0
106.112224200,179.0
106.199155720,205.0
106.286087240,191.0
106.373018760,169.0
106.459950280,180.0
106.546881800,182.0
106.633813320,163.0
106.720744840,194.0
106.807676360,177.0
106.894607880,174.0
106.981539400,177.0
107.068470920,205.0
107.155402440,176.0
107.242333960,208.0
107.329265480,198.0
107.416197000,205.0
107.503128520,223.0
107.590060040,262.0
107.676991560,311.0
107.763923080,442.0
107.850854600,397.0
107.937786120,360.0
108.024717640,289.0
108.111649160,284.0
108.198580680,324.0
108.285512200,292.0
108.372443720,233.0
108.459375240,222.0
108.546306760,220.0
108.633238280,184.0
108.720169800,213.0
108.807101320,183.0
108.894032840,212.0
108.980964360,182.0
109.067895880,187.0
109.154827400,214.0
109.241758920,238.0
109.328690440,211.0
109.415621960,229.0
109.502553480,281.0
109.589485000,309.0
109.676416520,353.0
109.763348040,433.0
109.850279560,641.0
109.937211080,1093.0
110.002409720,1670.0