File: Datos_proyecto_final/NaCl_DRX_sin_TT/NaCl_sin_TT.csv
[Measurement conditions]
Sample identification,NaCl_sin_TT
Comment,
Anode material,Cu
K-Alpha1 wavelength,1.5405980
K-Alpha2 wavelength,1.5444260
Ratio K-Alpha2/K-Alpha1,0.500
Divergence slit,Fixed,0.76mm
Monochromator used,NO
Generator voltage, 40
Tube current,  8
File date and time,24/Jun./2022 01:09
Unit cell,
h k l, 0 0 0
Scan axis,Gonio
Scan range,5.000000000,110.013276160
Scan step size,0.0217329
No. of points, 4832
Scan type,CONTINUOUS
Time per step,49.470
[Scan points]
Angle,Intensity
5.010866440,3908.0
5.097797960,3786.0
5.184729480,3600.0
5.271661000,3361.0
5.358592520,3363.0
5.445524040,3220.0
5.532455560,3159.0
5.619387080,2962.0
5.706318600,2853.0
5.793250120,2767.0
5.880181640,2660.0
5.967113160,2637.0
6.054044680,2643.0
6.140976200,2600.0
6.227907720,2547.0
6.314839240,2461.0
6.401770760,2478.0
6.488702280,2378.0
6.575633800,2471.0
6.662565320,2398.0
6.749496840,2335.0
6.836428360,2316.0
6.923359880,2440.0
7.010291400,2449.0
7.097222920,2360.0
7.184154440,2373.0
7.271085960,2292.0
7.358017480,2359.0
7.444949000,2373.0
7.531880520,2295.0
7.618812040,2324.0
7.705743560,2352.0
7.792675080,2257.0
7.879606600,2281.0
7.966538120,2346.0
8.053469640,2308.0
8.140401160,2322.0
8.227332680,2352.0
8.314264200,2325.0
8.401195720,2301.0
8.488127240,2327.0
8.575058760,2412.0
8.661990280,2341.0
8.748921800,2378.0
8.835853320,2364.0
8.922784840,2418.0
9.009716360,2330.0
9.096647880,2350.0
9.183579400,2427.0
9.270510920,2512.0
9.357442440,2394.0
9.444373960,2403.0
9.531305480,2437.0
9.618237000,2404.0
9.705168520,2478.0
9.792100040,2376.0
9.879031560,2426.0
9.965963080,2418.0
10.052894600,2378.0
10.139826120,2375.0
10.226757640,2439.0
10.313689160,2412.0
10.400620680,2457.0
10.487552200,2525.0
10.574483720,2513.0
10.661415240,2407.0
10.748346760,2456.0
10.835278280,2580.0
10.922209800,2455.0
11.009141320,2492.0
11.096072840,2528.0
11.183004360,2643.0
11.269935880,2904.0
11.356867400,3183.0
11.443798920,4077.0
11.530730440,9113.0
11.617661960,12023.0
11.704593480,3074.0
11.791525000,2753.0
11.878456520,2673.0
11.965388040,2504.0
12.052319560,2557.0
12.139251080,2524.0
12.226182600,2452.0
12.313114120,2558.0
12.400045640,2490.0
12.486977160,2398.0
12.573908680,2398.0
12.660840200,2429.0
12.747771720,2316.0
12.834703240,2360.0
12.921634760,2419.0
13.008566280,2352.0
13.095497800,2447.0
13.182429320,2379.0
13.269360840,2341.0
13.356292360,2372.0
13.443223880,2369.0
13.530155400,2333.0
13.617086920,2306.0
13.704018440,2331.0
13.790949960,2260.0
13.877881480,2280.0
13.964813000,2233.0
14.051744520,2229.0
14.138676040,2208.0
14.225607560,2102.0
14.312539080,2206.0
14.399470600,2189.0
14.486402120,2285.0
14.573333640,2233.0
14.660265160,2149.0
14.747196680,2122.0
14.834128200,2155.0
14.921059720,2083.0
15.007991240,2015.0
15.094922760,2048.0
15.181854280,2145.0
15.268785800,2109.0
15.355717320,2062.0
15.442648840,2002.0
15.529580360,2013.0
15.616511880,2042.0
15.703443400,1996.0
15.790374920,1967.0
15.877306440,2008.0
15.964237960,1927.0
16.051169480,1863.0
16.138101000,1923.0
16.225032520,1903.0
16.311964040,1899.0
16.398895560,1915.0
16.485827080,1902.0
16.572758600,1864.0
16.659690120,1706.0
16.746621640,1872.0
16.833553160,1717.0
16.920484680,1780.0
17.007416200,1799.0
17.094347720,1707.0
17.181279240,1757.0
17.268210760,1720.0
17.355142280,1718.0
17.442073800,1768.0
17.529005320,1720.0
17.615936840,1739.0
17.702868360,1678.0
17.789799880,1717.0
17.876731400,1715.0
17.963662920,1619.0
18.050594440,1640.0
18.137525960,1593.0
18.224457480,1653.0
18.311389000,1461.0
18.398320520,1588.0
18.485252040,1544.0
18.572183560,1629.0
18.659115080,1487.0
18.746046600,1603.0
18.832978120,1499.0
18.919909640,1509.0
19.006841160,1506.0
19.093772680,1518.0
19.180704200,1472.0
19.267635720,1459.0
19.354567240,1418.0
19.441498760,1446.0
19.528430280,1429.0
19.615361800,1530.0
19.702293320,1517.0
19.789224840,1418.0
19.876156360,1365.0
19.963087880,1363.0
20.050019400,1346.0
20.136950920,1350.0
20.223882440,1323.0
20.310813960,1470.0
20.397745480,1378.0
20.484677000,1453.0
20.571608520,1531.0
20.658540040,1850.0
20.745471560,1492.0
20.832403080,1314.0
20.919334600,1290.0
21.006266120,1341.0
21.093197640,1273.0
21.180129160,1261.0
21.267060680,1294.0
21.353992200,1177.0
21.440923720,1206.0
21.527855240,1211.0
21.614786760,1189.0
21.701718280,1123.0
21.788649800,1205.0
21.875581320,1145.0
21.962512840,1161.0
22.049444360,1105.0
22.136375880,1196.0
22.223307400,1068.0
22.310238920,1066.0
22.397170440,1083.0
22.484101960,1093.0
22.571033480,1102.0
22.657965000,1158.0
22.744896520,1106.0
22.831828040,1042.0
22.918759560,1026.0
23.005691080,1116.0
23.092622600,1084.0
23.179554120,1206.0
23.266485640,2183.0
23.353417160,3785.0
23.440348680,1373.0
23.527280200,1132.0
23.614211720,986.0
23.701143240,1061.0
23.788074760,970.0
23.875006280,942.0
23.961937800,957.0
24.048869320,1004.0
24.135800840,984.0
24.222732360,935.0
24.309663880,969.0
24.396595400,957.0
24.483526920,931.0
24.570458440,932.0
24.657389960,965.0
24.744321480,921.0
24.831253000,938.0
24.918184520,869.0
25.005116040,900.0
25.092047560,901.0
25.178979080,856.0
25.265910600,860.0
25.352842120,894.0
25.439773640,841.0
25.526705160,868.0
25.613636680,861.0
25.700568200,903.0
25.787499720,776.0
25.874431240,846.0
25.961362760,803.0
26.048294280,791.0
26.135225800,825.0
26.222157320,825.0
26.309088840,866.0
26.396020360,767.0
26.482951880,829.0
26.569883400,776.0
26.656814920,783.0
26.743746440,783.0
26.830677960,809.0
26.917609480,797.0
27.004541000,861.0
27.091472520,1000.0
27.178404040,1445.0
27.265335560,3306.0
27.352267080,3352.0
27.439198600,1289.0
27.526130120,853.0
27.613061640,848.0
27.699993160,792.0
27.786924680,765.0
27.873856200,746.0
27.960787720,686.0
28.047719240,756.0
28.134650760,776.0
28.221582280,739.0
28.308513800,834.0
28.395445320,871.0
28.482376840,1274.0
28.569308360,1231.0
28.656239880,766.0
28.743171400,782.0
28.830102920,776.0
28.917034440,842.0
29.003965960,1062.0
29.090897480,1076.0
29.177829000,832.0
29.264760520,776.0
29.351692040,733.0
29.438623560,747.0
29.525555080,742.0
29.612486600,774.0
29.699418120,734.0
29.786349640,723.0
29.873281160,786.0
29.960212680,733.0
30.047144200,748.0
30.134075720,793.0
30.221007240,776.0
30.307938760,758.0
30.394870280,774.0
30.481801800,873.0
30.568733320,1179.0
30.655664840,1343.0
30.742596360,1269.0
30.829527880,1357.0
30.916459400,1373.0
31.003390920,1599.0
31.090322440,1736.0
31.177253960,2344.0
31.264185480,3067.0
31.351117000,3974.0
31.438048520,8026.0
31.524980040,30380.0
31.611911560,136125.0
31.698843080,141206.0
31.785774600,37857.0
31.872706120,5770.0
31.959637640,3710.0
32.046569160,2527.0
32.133500680,1628.0
32.220432200,1373.0
32.307363720,1346.0
32.394295240,1302.0
32.481226760,1216.0
32.568158280,1141.0
32.655089800,1034.0
32.742021320,1057.0
32.828952840,1071.0
32.915884360,1030.0
33.002815880,1016.0
33.089747400,972.0
33.176678920,1009.0
33.263610440,1085.0
33.350541960,1026.0
33.437473480,910.0
33.524405000,888.0
33.611336520,851.0
33.698268040,814.0
33.785199560,855.0
33.872131080,831.0
33.959062600,807.0
34.045994120,760.0
34.132925640,799.0
34.219857160,750.0
34.306788680,770.0
34.393720200,765.0
34.480651720,811.0
34.567583240,754.0
34.654514760,811.0
34.741446280,731.0
34.828377800,738.0
34.915309320,712.0
35.002240840,652.0
35.089172360,690.0
35.176103880,659.0
35.263035400,716.0
35.349966920,839.0
35.436898440,732.0
35.523829960,627.0
35.610761480,680.0
35.697693000,668.0
35.784624520,632.0
35.871556040,694.0
35.958487560,682.0
36.045419080,663.0
36.132350600,610.0
36.219282120,600.0
36.306213640,587.0
36.393145160,603.0
36.480076680,602.0
36.567008200,607.0
36.653939720,625.0
36.740871240,590.0
36.827802760,551.0
36.914734280,568.0
37.001665800,556.0
37.088597320,555.0
37.175528840,565.0
37.262460360,516.0
37.349391880,552.0
37.436323400,550.0
37.523254920,574.0
37.610186440,552.0
37.697117960,577.0
37.784049480,501.0
37.870981000,484.0
37.957912520,491.0
38.044844040,515.0
38.131775560,503.0
38.218707080,515.0
38.305638600,486.0
38.392570120,481.0
38.479501640,527.0
38.566433160,461.0
38.653364680,500.0
38.740296200,465.0
38.827227720,458.0
38.914159240,475.0
39.001090760,445.0
39.088022280,483.0
39.174953800,450.0
39.261885320,467.0
39.348816840,493.0
39.435748360,474.0
39.522679880,489.0
39.609611400,432.0
39.696542920,444.0
39.783474440,454.0
39.870405960,431.0
39.957337480,420.0
40.044269000,466.0
40.131200520,432.0
40.218132040,462.0
40.305063560,460.0
40.391995080,457.0
40.478926600,410.0
40.565858120,487.0
40.652789640,522.0
40.739721160,551.0
40.826652680,589.0
40.913584200,439.0
41.000515720,455.0
41.087447240,443.0
41.174378760,390.0
41.261310280,413.0
41.348241800,400.0
41.435173320,429.0
41.522104840,459.0
41.609036360,378.0
41.695967880,395.0
41.782899400,421.0
41.869830920,447.0
41.956762440,401.0
42.043693960,421.0
42.130625480,422.0
42.217557000,394.0
42.304488520,387.0
42.391420040,406.0
42.478351560,332.0
42.565283080,394.0
42.652214600,382.0
42.739146120,380.0
42.826077640,386.0
42.913009160,384.0
42.999940680,423.0
43.086872200,396.0
43.173803720,419.0
43.260735240,464.0
43.347666760,427.0
43.434598280,454.0
43.521529800,433.0
43.608461320,379.0
43.695392840,476.0
43.782324360,423.0
43.869255880,467.0
43.956187400,501.0
44.043118920,479.0
44.130050440,500.0
44.216981960,491.0
44.303913480,476.0
44.390845000,475.0
44.477776520,500.0
44.564708040,505.0
44.651639560,509.0
44.738571080,512.0
44.825502600,613.0
44.912434120,709.0
44.999365640,835.0
45.086297160,1116.0
45.173228680,1892.0
45.260160200,5991.0
45.347091720,23788.0
45.434023240,25121.0
45.520954760,16886.0
45.607886280,3014.0
45.694817800,1218.0
45.781749320,785.0
45.868680840,642.0
45.955612360,539.0
46.042543880,496.0
46.129475400,504.0
46.216406920,481.0
46.303338440,424.0
46.390269960,470.0
46.477201480,427.0
46.564133000,444.0
46.651064520,392.0
46.737996040,433.0
46.824927560,409.0
46.911859080,418.0
46.998790600,398.0
47.085722120,362.0
47.172653640,413.0
47.259585160,401.0
47.346516680,395.0
47.433448200,424.0
47.520379720,390.0
47.607311240,393.0
47.694242760,467.0
47.781174280,688.0
47.868105800,522.0
47.955037320,428.0
48.041968840,386.0
48.128900360,359.0
48.215831880,407.0
48.302763400,417.0
48.389694920,391.0
48.476626440,384.0
48.563557960,391.0
48.650489480,345.0
48.737421000,386.0
48.824352520,342.0
48.911284040,340.0
48.998215560,347.0
49.085147080,312.0
49.172078600,345.0
49.259010120,299.0
49.345941640,330.0
49.432873160,325.0
49.519804680,303.0
49.606736200,348.0
49.693667720,338.0
49.780599240,323.0
49.867530760,348.0
49.954462280,331.0
50.041393800,327.0
50.128325320,362.0
50.215256840,328.0
50.302188360,376.0
50.389119880,326.0
50.476051400,324.0
50.562982920,324.0
50.649914440,310.0
50.736845960,312.0
50.823777480,294.0
50.910709000,314.0
50.997640520,343.0
51.084572040,311.0
51.171503560,328.0
51.258435080,297.0
51.345366600,312.0
51.432298120,307.0
51.519229640,312.0
51.606161160,285.0
51.693092680,304.0
51.780024200,304.0
51.866955720,278.0
51.953887240,276.0
52.040818760,262.0
52.127750280,293.0
52.214681800,321.0
52.301613320,271.0
52.388544840,271.0
52.475476360,293.0
52.562407880,245.0
52.649339400,268.0
52.736270920,261.0
52.823202440,275.0
52.910133960,236.0
52.997065480,246.0
53.083997000,266.0
53.170928520,264.0
53.257860040,257.0
53.344791560,279.0
53.431723080,284.0
53.518654600,296.0
53.605586120,352.0
53.692517640,462.0
53.779449160,829.0
53.866380680,701.0
53.953312200,649.0
54.040243720,360.0
54.127175240,279.0
54.214106760,286.0
54.301038280,292.0
54.387969800,288.0
54.474901320,308.0
54.561832840,260.0
54.648764360,261.0
54.735695880,223.0
54.822627400,283.0
54.909558920,278.0
54.996490440,275.0
55.083421960,314.0
55.170353480,279.0
55.257285000,305.0
55.344216520,289.0
55.431148040,281.0
55.518079560,279.0
55.605011080,270.0
55.691942600,308.0
55.778874120,280.0
55.865805640,343.0
55.952737160,349.0
56.039668680,377.0
56.126600200,451.0
56.213531720,684.0
56.300463240,2189.0
56.387394760,6778.0
56.474326280,3723.0
56.561257800,3667.0
56.648189320,1112.0
56.735120840,540.0
56.822052360,396.0
56.908983880,331.0
56.995915400,298.0
57.082846920,270.0
57.169778440,263.0
57.256709960,302.0
57.343641480,267.0
57.430573000,258.0
57.517504520,248.0
57.604436040,275.0
57.691367560,290.0
57.778299080,244.0
57.865230600,213.0
57.952162120,264.0
58.039093640,218.0
58.126025160,272.0
58.212956680,234.0
58.299888200,221.0
58.386819720,233.0
58.473751240,238.0
58.560682760,248.0
58.647614280,236.0
58.734545800,261.0
58.821477320,208.0
58.908408840,269.0
58.995340360,256.0
59.082271880,305.0
59.169203400,230.0
59.256134920,247.0
59.343066440,230.0
59.429997960,230.0
59.516929480,267.0
59.603861000,210.0
59.690792520,237.0
59.777724040,228.0
59.864655560,256.0
59.951587080,230.0
60.038518600,202.0
60.125450120,208.0
60.212381640,200.0
60.299313160,246.0
60.386244680,199.0
60.473176200,234.0
60.560107720,219.0
60.647039240,209.0
60.733970760,234.0
60.820902280,240.0
60.907833800,243.0
60.994765320,219.0
61.081696840,217.0
61.168628360,199.0
61.255559880,197.0
61.342491400,218.0
61.429422920,208.0
61.516354440,221.0
61.603285960,217.0
61.690217480,239.0
61.777149000,203.0
61.864080520,214.0
61.951012040,206.0
62.037943560,229.0
62.124875080,222.0
62.211806600,202.0
62.298738120,214.0
62.385669640,206.0
62.472601160,232.0
62.559532680,209.0
62.646464200,205.0
62.733395720,208.0
62.820327240,209.0
62.907258760,172.0
62.994190280,206.0
63.081121800,201.0
63.168053320,212.0
63.254984840,229.0
63.341916360,189.0
63.428847880,231.0
63.515779400,199.0
63.602710920,233.0
63.689642440,215.0
63.776573960,257.0
63.863505480,221.0
63.950437000,249.0
64.037368520,247.0
64.124300040,229.0
64.211231560,225.0
64.298163080,226.0
64.385094600,256.0
64.472026120,217.0
64.558957640,234.0
64.645889160,236.0
64.732820680,286.0
64.819752200,264.0
64.906683720,231.0
64.993615240,241.0
65.080546760,250.0
65.167478280,266.0
65.254409800,224.0
65.341341320,240.0
65.428272840,272.0
65.515204360,294.0
65.602135880,264.0
65.689067400,362.0
65.775998920,438.0
65.862930440,500.0
65.949861960,676.0
66.036793480,1515.0
66.123725000,6666.0
66.210656520,7357.0
66.297588040,3754.0
66.384519560,4443.0
66.471451080,1041.0
66.558382600,509.0
66.645314120,416.0
66.732245640,336.0
66.819177160,311.0
66.906108680,261.0
66.993040200,267.0
67.079971720,278.0
67.166903240,271.0
67.253834760,267.0
67.340766280,225.0
67.427697800,267.0
67.514629320,220.0
67.601560840,261.0
67.688492360,245.0
67.775423880,256.0
67.862355400,239.0
67.949286920,259.0
68.036218440,209.0
68.123149960,226.0
68.210081480,235.0
68.297013000,212.0
68.383944520,231.0
68.470876040,206.0
68.557807560,242.0
68.644739080,246.0
68.731670600,235.0
68.818602120,232.0
68.905533640,219.0
68.992465160,226.0
69.079396680,233.0
69.166328200,206.0
69.253259720,199.0
69.340191240,209.0
69.427122760,222.0
69.514054280,203.0
69.600985800,203.0
69.687917320,211.0
69.774848840,204.0
69.861780360,210.0
69.948711880,200.0
70.035643400,196.0
70.122574920,243.0
70.209506440,215.0
70.296437960,200.0
70.383369480,210.0
70.470301000,220.0
70.557232520,202.0
70.644164040,216.0
70.731095560,200.0
70.818027080,209.0
70.904958600,202.0
70.991890120,218.0
71.078821640,219.0
71.165753160,233.0
71.252684680,192.0
71.339616200,200.0
71.426547720,186.0
71.513479240,209.0
71.600410760,191.0
71.687342280,225.0
71.774273800,222.0
71.861205320,182.0
71.948136840,199.0
72.035068360,211.0
72.121999880,204.0
72.208931400,216.0
72.295862920,218.0
72.382794440,242.0
72.469725960,187.0
72.556657480,230.0
72.643589000,222.0
72.730520520,248.0
72.817452040,223.0
72.904383560,332.0
72.991315080,445.0
73.078246600,386.0
73.165178120,324.0
73.252109640,333.0
73.339041160,261.0
73.425972680,244.0
73.512904200,195.0
73.599835720,223.0
73.686767240,244.0
73.773698760,220.0
73.860630280,240.0
73.947561800,234.0
74.034493320,258.0
74.121424840,242.0
74.208356360,225.0
74.295287880,248.0
74.382219400,243.0
74.469150920,235.0
74.556082440,242.0
74.643013960,285.0
74.729945480,312.0
74.816877000,436.0
74.903808520,415.0
74.990740040,597.0
75.077671560,1151.0
75.164603080,3145.0
75.251534600,4070.0
75.338466120,2135.0
75.425397640,2513.0
75.512329160,1566.0
75.599260680,620.0
75.686192200,412.0
75.773123720,327.0
75.860055240,271.0
75.946986760,241.0
76.033918280,232.0
76.120849800,270.0
76.207781320,243.0
76.294712840,216.0
76.381644360,243.0
76.468575880,205.0
76.555507400,247.0
76.642438920,241.0
76.729370440,199.0
76.816301960,223.0
76.903233480,212.0
76.990165000,225.0
77.077096520,207.0
77.164028040,202.0
77.250959560,217.0
77.337891080,195.0
77.424822600,199.0
77.511754120,219.0
77.598685640,198.0
77.685617160,206.0
77.772548680,204.0
77.859480200,198.0
77.946411720,172.0
78.033343240,199.0
78.120274760,191.0
78.207206280,197.0
78.294137800,199.0
78.381069320,189.0
78.468000840,196.0
78.554932360,190.0
78.641863880,168.0
78.728795400,169.0
78.815726920,188.0
78.902658440,197.0
78.989589960,182.0
79.076521480,189.0
79.163453000,185.0
79.250384520,180.0
79.337316040,182.0
79.424247560,204.0
79.511179080,148.0
79.598110600,194.0
79.685042120,209.0
79.771973640,205.0
79.858905160,165.0
79.945836680,174.0
80.032768200,206.0
80.119699720,174.0
80.206631240,185.0
80.293562760,187.0
80.380494280,176.0
80.467425800,178.0
80.554357320,158.0
80.641288840,206.0
80.728220360,194.0
80.815151880,174.0
80.902083400,204.0
80.989014920,179.0
81.075946440,191.0
81.162877960,201.0
81.249809480,192.0
81.336741000,194.0
81.423672520,183.0
81.510604040,162.0
81.597535560,180.0
81.684467080,174.0
81.771398600,193.0
81.858330120,181.0
81.945261640,206.0
82.032193160,172.0
82.119124680,173.0
82.206056200,171.0
82.292987720,197.0
82.379919240,207.0
82.466850760,184.0
82.553782280,171.0
82.640713800,193.0
82.727645320,172.0
82.814576840,189.0
82.901508360,183.0
82.988439880,203.0
83.075371400,217.0
83.162302920,199.0
83.249234440,194.0
83.336165960,211.0
83.423097480,250.0
83.510029000,276.0
83.596960520,314.0
83.683892040,400.0
83.770823560,758.0
83.857755080,1987.0
83.944686600,2503.0
84.031618120,1345.0
84.118549640,1362.0
84.205481160,1376.0
84.292412680,653.0
84.379344200,347.0
84.466275720,276.0
84.553207240,211.0
84.640138760,213.0
84.727070280,209.0
84.814001800,179.0
84.900933320,210.0
84.987864840,199.0
85.074796360,177.0
85.161727880,212.0
85.248659400,183.0
85.335590920,202.0
85.422522440,176.0
85.509453960,182.0
85.596385480,163.0
85.683317000,200.0
85.770248520,180.0
85.857180040,159.0
85.944111560,179.0
86.031043080,182.0
86.117974600,174.0
86.204906120,157.0
86.291837640,177.0
86.378769160,182.0
86.465700680,169.0
86.552632200,183.0
86.639563720,134.0
86.726495240,177.0
86.813426760,178.0
86.900358280,159.0
86.987289800,155.0
87.074221320,175.0
87.161152840,143.0
87.248084360,122.0
87.335015880,158.0
87.421947400,169.0
87.508878920,183.0
87.595810440,162.0
87.682741960,153.0
87.769673480,178.0
87.856605000,162.0
87.943536520,153.0
88.030468040,136.0
88.117399560,160.0
88.204331080,157.0
88.291262600,148.0
88.378194120,153.0
88.465125640,170.0
88.552057160,168.0
88.638988680,143.0
88.725920200,162.0
88.812851720,171.0
88.899783240,153.0
88.986714760,139.0
89.073646280,148.0
89.160577800,171.0
89.247509320,166.0
89.334440840,148.0
89.421372360,185.0
89.508303880,142.0
89.595235400,133.0
89.682166920,160.0
89.769098440,196.0
89.856029960,135.0
89.942961480,160.0
90.029893000,171.0
90.116824520,195.0
90.203756040,201.0
90.290687560,379.0
90.377619080,412.0
90.464550600,286.0
90.551482120,270.0
90.638413640,302.0
90.725345160,242.0
90.812276680,170.0
90.899208200,167.0
90.986139720,167.0
91.073071240,153.0
91.160002760,132.0
91.246934280,151.0
91.333865800,178.0
91.420797320,161.0
91.507728840,144.0
91.594660360,137.0
91.681591880,150.0
91.768523400,158.0
91.855454920,145.0
91.942386440,160.0
92.029317960,177.0
92.116249480,139.0
92.203181000,177.0
92.290112520,167.0
92.377044040,166.0
92.463975560,157.0
92.550907080,166.0
92.637838600,128.0
92.724770120,174.0
92.811701640,185.0
92.898633160,145.0
92.985564680,145.0
93.072496200,158.0
93.159427720,157.0
93.246359240,153.0
93.333290760,159.0
93.420222280,160.0
93.507153800,156.0
93.594085320,138.0
93.681016840,117.0
93.767948360,126.0
93.854879880,141.0
93.941811400,130.0
94.028742920,159.0
94.115674440,153.0
94.202605960,134.0
94.289537480,155.0
94.376469000,141.0
94.463400520,150.0
94.550332040,156.0
94.637263560,165.0
94.724195080,162.0
94.811126600,160.0
94.898058120,147.0
94.984989640,130.0
95.071921160,153.0
95.158852680,174.0
95.245784200,143.0
95.332715720,153.0
95.419647240,158.0
95.506578760,157.0
95.593510280,143.0
95.680441800,137.0
95.767373320,145.0
95.854304840,152.0
95.941236360,142.0
96.028167880,174.0
96.115099400,145.0
96.202030920,142.0
96.288962440,142.0
96.375893960,155.0
96.462825480,138.0
96.549757000,137.0
96.636688520,140.0
96.723620040,147.0
96.810551560,167.0
96.897483080,136.0
96.984414600,161.0
97.071346120,145.0
97.158277640,128.0
97.245209160,158.0
97.332140680,158.0
97.419072200,141.0
97.506003720,165.0
97.592935240,146.0
97.679866760,159.0
97.766798280,150.0
97.853729800,158.0
97.940661320,158.0
98.027592840,162.0
98.114524360,147.0
98.201455880,164.0
98.288387400,131.0
98.375318920,174.0
98.462250440,167.0
98.549181960,138.0
98.636113480,147.0
98.723045000,154.0
98.809976520,173.0
98.896908040,177.0
98.983839560,164.0
99.070771080,159.0
99.157702600,141.0
99.244634120,169.0
99.331565640,168.0
99.418497160,169.0
99.505428680,158.0
99.592360200,181.0
99.679291720,167.0
99.766223240,163.0
99.853154760,180.0
99.940086280,176.0
100.027017800,155.0
100.113949320,173.0
100.200880840,136.0
100.287812360,177.0
100.374743880,174.0
100.461675400,175.0
100.548606920,194.0
100.635538440,198.0
100.722469960,231.0
100.809401480,211.0
100.896333000,331.0
100.983264520,574.0
101.070196040,1109.0
101.157127560,1143.0
101.244059080,660.0
101.330990600,528.0
101.417922120,725.0
101.504853640,641.0
101.591785160,370.0
101.678716680,272.0
101.765648200,207.0
101.852579720,210.0
101.939511240,200.0
102.026442760,167.0
102.113374280,172.0
102.200305800,166.0
102.287237320,194.0
102.374168840,184.0
102.461100360,188.0
102.548031880,163.0
102.634963400,172.0
102.721894920,181.0
102.808826440,161.0
102.895757960,183.0
102.982689480,162.0
103.069621000,181.0
103.156552520,142.0
103.243484040,180.0
103.330415560,169.0
103.417347080,170.0
103.504278600,160.0
103.591210120,174.0
103.678141640,179.0
103.765073160,175.0
103.852004680,170.0
103.938936200,165.0
104.025867720,170.0
104.112799240,162.0
104.199730760,175.0
104.286662280,180.0
104.373593800,163.0
104.460525320,175.0
104.547456840,187.0
104.634388360,174.0
104.721319880,169.0
104.808251400,179.0
104.895182920,168.0
104.982114440,160.0
105.069045960,165.0
105.155977480,180.0
105.242909000,177.0
105.329840520,192.0
105.416772040,204.0
105.503703560,175.0
105.590635080,150.0
105.677566600,155.0
105.764498120,175.0
105.851429640,156.0
105.938361160,178.0
106.025292680,177.0
106.112224200,167.0
106.199155720,175.0
106.286087240,196.0
106.373018760,178.0
106.459950280,163.0
106.546881800,172.0
106.633813320,199.0
106.720744840,193.0
106.807676360,191.0
106.894607880,196.0
106.981539400,170.0
107.068470920,197.0
107.155402440,181.0
107.242333960,185.0
107.329265480,172.0
107.416197000,207.0
107.503128520,244.0
107.590060040,304.0
107.676991560,418.0
107.763923080,396.0
107.850854600,315.0
107.937786120,263.0
108.024717640,314.0
108.111649160,298.0
108.198580680,298.0
108.285512200,223.0
108.372443720,234.0
108.459375240,236.0
108.546306760,202.0
108.633238280,203.0
108.720169800,212.0
108.807101320,176.0
108.894032840,208.0
108.980964360,227.0
109.067895880,213.0
109.154827400,248.0
109.241758920,229.0
109.328690440,267.0
109.415621960,244.0
109.502553480,280.0
109.589485000,297.0
109.676416520,396.0
109.763348040,577.0
109.850279560,1019.0
109.937211080,2111.0
110.002409720,2644.0