File: Difraccion_Rayos_X/Datos/AluminioGrupo5/Aluminio_grupo5.xrdml
<?xml version="1.0" encoding="UTF-8"?>
<xrdMeasurements xmlns="http://www.xrdml.com/XRDMeasurement/1.7" xmlns:xsi="http://www.w3.org/2001/XMLSchema-instance" xsi:schemaLocation="http://www.xrdml.com/XRDMeasurement/1.7 http://www.xrdml.com/XRDMeasurement/1.7/XRDMeasurement.xsd" status="Completed">
	<comment>
		<entry/>
	</comment>
	<sample type="To be analyzed">
		<id>Aluminio_grupo5</id>
		<name></name>
		<preparedBy></preparedBy>
	</sample>
	<xrdMeasurement measurementType="Scan" status="Completed" sampleMode="Reflection">
		<usedWavelength intended="K-Alpha 1">
			<kAlpha1 unit="Angstrom">1.5405980</kAlpha1>
			<kAlpha2 unit="Angstrom">1.5444260</kAlpha2>
			<kBeta unit="Angstrom">1.3922500</kBeta>
			<ratioKAlpha2KAlpha1>0.5000</ratioKAlpha2KAlpha1>
		</usedWavelength>
		<incidentBeamPath>
			<radius unit="mm">145.00</radius>
			<xRayTube id="1010048" name="Empyrean Cu LFF HR (9430 033 7310x) DK420669">
				<tension unit="kV">40.0</tension>
				<current unit="mA">7.5</current>
				<anodeMaterial>Cu</anodeMaterial>
				<focus type="Line">
					<length unit="mm">12.0</length>
					<width unit="mm">0.4</width>
					<takeOffAngle unit="deg">6.0</takeOffAngle>
				</focus>
			</xRayTube>
			<filter id="20010004" name="Beta-filter Nickel">
				<material>Ni</material>
				<thickness unit="mm">0.020</thickness>
			</filter>
			<sollerSlit id="21010002" name="Soller slits 0.04 rad.">
				<opening unit="rad">0.0400</opening>
			</sollerSlit>
			<mask id="22031000" name="Fixed mask 13 mm">
				<width unit="mm">9.00</width>
			</mask>
			<divergenceSlit id="22120002" name="Divergence slit 1/2Â°" xsi:type="fixedDivergenceSlitType">
				<distanceToSample unit="mm">50.00</distanceToSample>
				<height unit="mm">0.76</height>
			</divergenceSlit>
		</incidentBeamPath>
		<sampleMovement xsi:type="spinningSampleMovementType">
			<spinnerRevolutionTime unit="seconds">1.0</spinnerRevolutionTime>
		</sampleMovement>
		<diffractedBeamPath>
			<radius unit="mm">145.00</radius>
			<antiScatterSlit id="22090040" name="AS slit 9 mm" xsi:type="fixedAntiScatterSlitType">
				<height unit="mm">9.00</height>
			</antiScatterSlit>
			<sollerSlit id="21020003" name="Large Soller slits 0.04 rad.">
				<opening unit="rad">0.0400</opening>
			</sollerSlit>
			<detector id="7010019" name="PIXcel1D-Medipix3 detector" xsi:type="rtmsDetectorType">
				<phd unit="keV">
					<lowerLevel>4.0</lowerLevel>
					<upperLevel>11.3</upperLevel>
				</phd>
				<mode>Scanning</mode>
				<activeLength unit="deg">5.542</activeLength>
			</detector>
		</diffractedBeamPath>
		<scan appendNumber="0" mode="Continuous" scanAxis="Gonio" status="Completed">
			<header>
				<startTimeStamp>2022-04-27T23:51:05+02:00</startTimeStamp>
				<endTimeStamp>2022-04-28T00:28:14+02:00</endTimeStamp>
				<author>
					<name>Instrument</name>
				</author>
				<source>
					<applicationSoftware version="Aeris_1.1b">Data Collector</applicationSoftware>
					<instrumentControlSoftware version="1.2.0 20180625">AERIS</instrumentControlSoftware>
					<instrumentID>208441</instrumentID>
				</source>
			</header>
			<dataPoints>
				<positions axis="2Theta" unit="deg">
					<startPosition>5.00135831</startPosition>
					<endPosition>99.99849340</endPosition>
				</positions>
				<positions axis="Omega" unit="deg">
					<startPosition>2.50067916</startPosition>
					<endPosition>49.99924670</endPosition>
				</positions>
				<commonCountingTime unit="seconds">13.770</commonCountingTime>
				<intensities 790 783 783 793 776 805 814 778 798 793 878 819 822 802 754 769 804 754 709 781 798 777 802 753 746 765 757 776 786 791 792 764 707 744 788 786 744 737 743 778 746 751 716 757 698 708 715 721 686 710 765 751 722 760 708 712 708 731 683 740 734 746 769 790 765 700 748 752 658 727 706 686 759 704 744 703 703 699 692 717 680 692 667 696 716 718 667 683 663 707 703 737 671 634 703 710 671 691 698 683 658 649 700 672 692 669 653 663 734 658 618 673 681 690 667 627 684 632 666 664 664 670 674 648 640 648 696 697 604 592 648 662 641 664 654 635 662 658 638 655 661 633 697 680 642 645 656 669 665 603 642 682 619 667 629 616 696 667 593 619 646 677 672 652 573 634 670 663 667 645 626 614 629 648 630 579 587 624 619 613 647 632 630 619 604 620 632 633 594 616 616 630 603 641 582 613 657 627 653 590 633 576 591 624 670 607 589 584 600 581 610 593 611 573 550 613 621 598 567 619 594 600 588 570 583 565 609 587 570 560 621 634 584 557 576 571 584 560 606 555 603 565 549 607 592 539 555 584 572 621 561 541 547 551 564 643 591 566 597 582 574 562 591 586 595 567 606 606 589 547 550 586 598 587 562 553 567 567 633 581 580 554 559 531 569 575 591 543 546 577 586 563 600 536 556 530 551 556 570 566 560 584 585 558 589 555 560 534 501 570 553 542 560 517 550 526 534 528 536 556 568 554 571 538 594 582 565 565 542 559 529 541 512 564 546 505 541 553 582 538 514 523 504 553 545 567 523 552 514 531 514 520 553 518 497 518 501 505 493 551 545 554 571 588 514 569 542 557 555 536 569 531 527 604 547 571 536 552 501 491 527 501 515 540 530 527 480 497 517 496 522 497 539 506 499 521 533 519 504 512 527 557 493 511 495 521 493 510 531 550 529 515 512 535 529 484 534 551 561 515 512 513 501 528 458 532 450 518 518 553 525 517 509 537 481 509 523 550 500 479 492 497 462 500 478 534 479 534 459 468 519 484 460 544 510 511 457 507 495 445 476 491 542 527 481 459 485 489 551 510 485 492 500 486 485 502 510 492 473 491 455 424 504 524 515 464 477 507 473 487 526 458 515 506 465 435 476 501 489 473 500 474 493 455 459 490 517 496 471 496 503 501 489 497 493 489 528 515 501 434 473 490 478 476 472 483 439 476 460 457 462 472 488 486 465 498 462 489 464 492 492 493 496 470 496 442 486 475 469 485 454 444 473 445 465 440 452 486 497 473 464 484 446 449 498 468 432 462 465 485 477 457 451 456 476 442 458 458 432 453 448 402 451 479 422 451 434 463 490 441 436 423 460 427 443 444 510 426 426 473 456 420 451 494 476 455 456 485 453 439 426 460 448 429 456 493 461 502 499 459 436 436 425 457 436 416 442 431 452 421 460 461 446 437 476 451 445 462 469 442 448 432 441 451 444 486 443 454 432 420 430 460 461 467 467 432 446 447 455 462 442 410 473 446 428 422 417 463 460 434 475 467 441 434 473 409 459 439 477 435 474 462 415 418 412 407 435 399 472 422 428 404 434 419 433 418 398 397 445 430 454 436 430 437 371 426 459 429 435 449 439 441 453 406 445 436 398 447 435 435 419 447 466 417 416 430 442 474 421 452 429 445 423 417 412 427 433 457 439 420 425 454 405 452 446 440 469 416 431 438 449 424 428 407 443 437 462 437 444 427 432 461 440 445 481 460 450 447 430 438 426 398 413 422 432 421 464 445 438 446 395 401 454 425 437 433 436 441 460 415 401 427 372 402 386 401 405 423 429 405 408 378 426 428 451 404 421 427 440 392 415 452 427 444 386 430 425 420 424 404 407 450 455 429 402 364 460 438 428 439 422 469 374 437 450 425 425 414 417 422 418 398 416 410 420 419 402 425 435 416 412 444 438 401 456 399 380 420 412 411 429 385 431 437 424 427 399 444 384 417 400 451 408 412 444 422 448 435 431 463 390 454 408 393 465 393 405 386 429 436 391 402 424 415 420 429 382 407 422 419 426 411 396 403 404 415 432 412 405 424 415 390 435 421 393 448 380 422 405 414 388 422 391 415 388 401 430 425 386 395 368 386 435 436 459 384 409 415 403 394 430 392 461 419 408 385 450 421 400 410 431 418 416 376 431 384 416 404 417 410 383 389 425 432 392 401 399 413 441 374 366 446 388 429 442 422 405 380 378 397 426 422 405 381 423 419 394 401 402 413 419 385 422 408 383 413 399 373 403 418 378 414 418 424 390 409 431 397 427 393 431 406 386 394 394 394 362 407 409 390 380 431 411 392 371 381 408 413 397 400 381 402 361 408 405 419 400 417 417 359 400 403 391 359 390 388 380 394 428 396 387 394 409 395 375 393 385 449 389 390 374 418 409 399 415 394 425 375 365 429 421 351 366 382 373 360 368 334 368 370 394 375 403 384 388 338 385 386 350 375 378 397 386 417 368 382 390 390 395 391 382 381 414 405 386 385 390 364 394 393 355 374 387 390 397 369 356 374 378 395 337 402 400 374 404 396 359 409 385 374 370 418 395 356 355 383 352 396 374 349 347 391 373 372 384 358 404 399 365 369 419 392 365 371 377 361 381 377 377 362 392 399 389 367 396 350 386 395 346 435 391 379 376 370 368 374 351 400 362 384 408 434 373 374 418 400 373 371 351 366 371 348 408 330 355 398 362 390 401 435 381 372 347 365 403 359 368 384 401 382 346 368 334 357 363 359 394 379 345 368 415 347 355 372 384 350 365 360 358 366 377 375 367 369 357 360 391 352 351 386 352 353 355 375 387 363 388 353 364 361 367 347 370 407 395 375 334 377 390 396 354 380 345 376 367 368 373 373 408 382 384 356 363 377 360 361 374 346 386 372 332 341 347 365 367 353 371 360 377 367 373 352 325 377 368 385 409 362 402 382 390 356 329 359 342 359 353 378 401 324 362 397 352 348 332 390 339 387 355 361 340 383 367 356 379 360 368 386 368 366 416 358 363 382 358 301 380 356 350 340 367 352 376 339 353 354 340 382 352 336 383 379 379 328 340 377 392 347 334 373 368 354 355 359 379 349 409 394 359 375 341 364 371 367 311 365 391 364 385 361 349 355 366 349 369 388 318 334 353 352 311 324 361 352 359 337 365 327 342 346 347 307 351 332 333 358 351 336 375 340 351 396 335 337 361 347 348 343 363 384 356 355 369 356 344 378 329 371 348 353 340 364 363 344 317 353 375 329 375 352 304 332 344 329 353 391 359 348 318 372 346 341 340 357 315 372 360 342 352 370 374 331 380 355 321 364 364 314 364 333 337 367 332 352 371 348 374 398 355 318 351 342 331 327 352 330 339 337 338 357 375 397 369 320 339 331 321 321 331 340 327 302 355 355 339 337 349 299 373 397 323 316 337 324 334 337 375 321 376 341 349 328 346 306 338 378 351 353 331 352 340 344 360 316 362 342 381 327 342 318 392 348 367 359 343 366 312 314 355 313 318 365 321 330 322 338 291 364 338 362 341 330 383 317 346 322 310 299 336 327 329 336 351 351 341 361 350 347 327 360 370 326 337 326 376 314 367 331 353 339 321 307 347 339 349 371 342 336 312 337 361 340 323 349 326 339 358 313 318 344 366 311 330 370 358 325 344 319 361 368 317 339 312 332 315 309 328 324 301 371 348 318 304 316 337 328 309 299 363 315 318 314 346 344 300 321 309 312 358 331 326 321 316 308 315 329 354 328 337 344 316 296 351 297 332 310 326 301 347 310 299 326 344 313 345 326 298 320 308 356 352 303 352 321 314 353 340 342 335 311 346 334 340 303 317 319 322 328 342 304 342 308 320 313 355 310 339 343 339 324 286 321 336 341 281 324 313 310 333 279 317 329 306 320 322 312 310 290 321 314 286 322 351 296 280 295 306 293 319 326 312 319 308 321 294 334 317 303 283 289 294 286 309 358 304 331 342 292 312 319 314 286 321 351 284 328 294 305 297 306 331 322 327 320 286 342 315 342 298 293 317 296 272 295 314 344 313 329 312 293 293 306 315 296 292 286 317 282 308 320 291 305 325 355 301 280 242 293 300 317 286 273 305 298 299 322 314 304 307 296 275 323 292 313 311 278 312 295 303 304 301 332 320 328 305 301 284 277 329 321 300 313 311 289 285 307 301 316 303 324 305 284 329 311 282 300 287 296 284 276 316 306 316 288 285 312 289 338 306 317 288 319 315 305 307 287 328 270 248 267 293 300 297 270 305 286 280 289 304 292 306 315 285 292 320 317 300 240 288 287 271 282 292 282 291 322 281 303 310 296 302 267 318 289 308 291 272 332 305 312 294 289 312 317 307 294 315 244 313 318 279 285 277 273 283 256 277 327 279 297 297 272 263 304 294 275 286 267 266 279 315 266 303 293 277 274 283 281 298 271 275 298 277 292 305 280 273 247 288 283 280 296 299 295 268 315 275 300 267 245 298 266 286 281 275 266 300 265 274 264 304 273 264 278 301 257 297 284 247 264 276 279 318 302 271 257 264 286 285 249 243 291 260 286 293 270 273 239 281 257 288 293 271 279 301 283 266 284 292 288 278 235 290 288 270 300 248 282 280 277 283 246 284 260 273 294 246 316 287 277 296 260 260 247 257 291 298 268 285 276 261 224 296 236 257 273 275 303 266 263 275 287 234 267 264 250 263 221 260 272 226 266 289 244 247 272 302 277 263 249 311 286 271 293 271 293 267 248 243 242 264 239 280 285 267 261 273 269 296 273 282 229 262 264 262 246 243 301 233 249 269 298 242 245 243 267 280 250 242 267 247 283 249 236 271 242 246 249 256 261 264 296 260 275 239 282 273 246 290 283 248 245 237 268 258 279 277 229 286 260 258 228 274 248 259 242 272 257 258 246 265 256 267 229 272 227 251 268 235 275 245 258 246 240 236 247 256 273 257 246 233 265 275 240 285 272 266 257 258 268 226 279 299 265 241 235 265 250 260 265 267 230 236 267 217 240 237 241 226 266 225 261 243 261 278 223 250 231 259 248 258 233 243 228 242 247 241 256 259 231 244 216 223 223 228 242 233 228 271 233 215 240 226 221 202 256 209 223 232 223 226 236 235 262 203 206 228 227 275 269 250 244 218 236 230 237 240 256 215 222 225 234 264 238 234 220 219 232 225 223 247 247 260 257 220 225 227 233 222 235 226 218 222 229 265 264 240 258 236 208 208 220 232 232 227 215 221 244 205 235 211 219 259 217 183 237 250 228 232 230 217 257 243 237 206 241 220 234 195 238 230 242 232 226 239 234 206 208 228 207 221 227 199 202 247 239 223 213 220 234 238 225 239 198 226 229 197 206 226 207 206 225 213 197 219 216 274 224 224 220 230 206 228 236 189 214 226 225 237 215 216 203 232 237 221 224 215 206 224 212 212 225 194 259 220 226 213 222 194 226 231 222 228 225 212 192 217 215 210 190 232 206 233 219 211 220 236 215 191 198 222 229 211 240 218 258 236 216 210 216 208 203 217 223 237 230 221 222 234 237 214 217 204 239 222 227 212 192 219 263 209 225 214 232 206 240 197 203 212 181 203 205 175 227 217 232 196 186 233 219 225 210 182 197 187 217 201 202 212 225 215 210 216 207 192 208 183 175 213 200 236 237 205 162 218 199 208 186 211 217 205 189 205 182 193 222 210 188 200 212 204 224 209 220 198 233 212 211 193 195 193 205 200 202 213 198 210 177 243 215 204 194 177 189 205 213 186 208 213 227 211 180 205 208 203 238 227 205 215 194 206 203 230 210 212 209 207 211 220 193 222 218 213 237 231 196 205 210 242 226 248 236 219 229 214 194 233 235 214 215 233 240 208 239 219 200 199 215 207 201 183 196 179 191 198 171 195 181 197 200 185 177 200 206 211 205 203 219 191 191 203 188 200 181 184 190 201 196 184 223 197 192 194 199 198 181 187 172 205 190 188 189 181 209 198 170 207 198 205 206 203 176 201 207 191 198 184 218 168 193 211 194 197 205 191 156 191 201 186 198 197 186 173 212 204 171 179 192 171 176 211 179 217 207 206 192 196 193 206 188 202 181 212 198 208 229 205 202 205 213 196 212 204 201 216 220 172 209 203 198 167 190 184 203 166 193 179 188 207 174 178 174 221 185 183 205 178 177 194 174 190 167 190 181 196 188 191 196 183 179 204 171 169 179 187 211 206 162 205 193 217 185 196 203 204 178 230 200 203 202 215 194 224 224 237 238 217 277 227 239 259 258 236 278 217 239 242 241 214 263 233 225 243 208 223 204 183 197 211 190 208 199 205 176 174 163 202 196 197 184 157 188 180 154 175 208 166 173 178 161 160 169 175 177 198 158 161 162 155 139 170 185 169 171 165 147 178 156 172 173 154 186 179 171 174 168 167 186 180 192 153 160 183 182 152 161 193 179 192 175 202 193 196 170 171 185 174 183 167 147 154 160 163 181 178 172 191 152 170 158 175 145 168 168 158 158 175 174 146 148 165 165 174 160 179 176 175 165 184 153 169 171 178 161 176 168 175 174 151 194 163 187 155 167 167 174 189 176 150 163 192 160 180 168 156 175 196 165 162 191 217 181 153 184 179 199 207 193 213 220 198 185 197 182 179 207 201 159 186 193 187 181 178 202 169 170 180 205 187 178 186 193 173 196 192 173 187 150 174 173 183 137 160 164 163 169 177 170 160 152 150 156 153 180 162 166 165 164 162 158 167 162 160 158 151 177 146 163 172 163 142 141 164 163 147 163 156 160 146 173 153 125 145 149 170 190 138 156 174 183 153 175 178 157 156 164 154 179 178 154 175 178 157 167 151 149 137 157 166 143 172 162 172 149 148 168 173 167 152 160 183 161 146 154 158 129 149 161 159 168 144 140 167 161 170 162 168 158 165 154 160 175 159 154 153 172 137 169 161 179 143 157 151 148 161 167 149 154 147 141 157 156 143 153 165 141 145 149 136 169 132 172 157 150 161 155 146 160 143 152 164 151 156 155 169 121 156 156 154 175 151 163 167 165 151 162 162 149 150 141 148 155 149 150 159 140 147 138 131 147 123 156 143 159 150 144 150 145 165 149 159 136 152 171 176 123 158 155 140 141 134 150 162 143 146 173 144 142 146 147 140 145 152 138 144 161 139 122 170 159 157 157 152 133 150 143 177 145 133 149 118 185 141 175 151 141 146 152 131 164 191 164 154 140 144 140 160 139 174 157 135 142 157 147 184 138 143 153 149 141 148 156 115 135 151 150 163 143 142 147 122 134 151 152 151 159 119 130 145 127 152 172 130 147 128 148 140 145 131 144 133 145 157 121 142 129 143 143 162 155 129 146 147 129 134 143 149 162 151 153 137 114 167 146 148 149 154 156 159 152 160 149 144 165 153 154 145 154 125 145 167 158 131 164 165 159 166 161 141 147 157 141 153 175 140 132 168 138 145 163 135 159 133 144 142 142 135 134 136 130 139 144 147 132 139 159 146 136 149 145 149 138 131 139 132 138 121 136 141 132 148 155 136 142 157 136 146 117 165 141 147 146 131 143 143 141 146 134 125 134 123 161 149 111 146 166 135 160 127 149 166 144 134 130 127 150 123 129 123 154 127 140 122 143 153 146 133 150 145 141 118 128 130 131 154 128 140 133 136 153 140 144 120 147 122 144 119 121 137 139 152 123 132 157 117 127 123 162 139 134 166 128 148 148 143 125 118 159 115 163 133 142 135 153 140 142 158 145 165 151 149 149 139 154 135 153 165 136 146 138 146 135 143 135 135 138 141 145 118 157 133 137 122 149 137 139 123 129 150 146 150 132 149 151 131 117 149 127 129 120 172 131 128 132 121 141 131 120 120 135 136 127 140 140 126 125 135 134 141 125 114 154 120 158 139 136 141 108 142 133 143 135 122 119 127 118 129 120 133 118 141 148 153 133 127 123 145 142 138 136 141 127 124 117 137 127 106 148 125 137 150 132 161 103 138 137 150 150 119 151 122 111 126 137 139 122 143 148 129 126 119 145 145 128 144 132 112 137 118 143 135 124 142 143 125 144 120 127 131 154 131 125 126 125 137 147 126 111 169 151 119 141 154 112 135 137 141 114 144 151 128 119 117 135 145 135 121 113 134 131 112 137 133 132 124 124 133 124 139 121 149 128 127 104 139 129 125 142 142 140 103 125 128 152 136 149 126 128 144 142 132 144 144 129 136 119 153 130 142 139 155 147 150 145 133 148 143 140 135 132 150 163 152 134 164 136 150 163 140 132 159 124 132 148 137 158 150 162 140 129 114 127 139 112 137 135 131 132 139 117 149 131 145 137 125 113 122 150 128 137 149 135 113 133 133 138 129 141 106 139 150 145 137 128 120 138 134 139 129 111 134 129 158 118 140 117 129 117 133 135 118 143 134 122 94 119 139 125 126 121 125 137 148 137 141 100 130 131 135 122 118 123 130 138 127 112 142 142 152 132 120 145 119 138 129 99 131 149 140 133 145 139 119 113 126 119 119 144 130 140 130 121 134 123 138 135 111 132 116 124 123 129 118 133 137 122 112 126 121 115 119 132 139 135 130 115 116 113 140 125 146 127 143 142 124 137 124 125 149 137 126 156 135 143 134 145 155 142 168 144 185 151 150 175 147 140 146 161 157 173 126 142 150 128 163 137 144 161 134 128 121 143 126 142 139 133 135 109 126 154 143 134 144 143 122 118 121 146 128 140 138 135 123 146 126 117 126 111 140 120 121 142 141 139 115 129 146 139 120 113 145 143 159 119 133 125 143 141 126 117 138 132 133 126 111 130 144 127 129 127 124 118 131 121 131 131 137 110 114 125 124 139 147 130 127 121 107 127 138 129 135 139 119 130 126 147 131 102 113 129 111 128 112 137 119 115 129 128 114 125 150 127 118 138 127 130 129 144 125 132 141 129 142 151 126 127 134 150 155 130 130 140 122 171 151 146 124 142 164 151 146 150 145 148 148 151 149 156 149 155 168 158 135 151 152 150 173 156 174 159 134 161 131 152 189 151 131 173 162 152 149 157 184 145 141 176 166 159 178 161 197 133 175 177 177 196 159 160 180 173 159 175 185 186 149 164 160 190 148 170 158 163 179 163 161 159 201 172 194 191 197 207 205 217 212 198 187 207 213 205 208 196 205 185 202 233 259 234 214 265 272 233 223 260 265 308 288 306 286 284 318 294 318 331 348 359 388 398 406 404 434 437 451 456 482 536 560 568 608 654 694 780 815 853 974 1048 1045 1212 1319 1333 1499 1614 1830 1914 2081 2310 2561 2783 3002 3133 3410 3639 3948 4199 4308 4663 4742 5011 5166 5251 5486 5491 5687 5678 5897 5734 5813 5794 5715 5543 5492 5203 5075 4906 4778 4441 4201 3969 3816 3668 3378 3072 2844 2744 2429 2362 2129 1986 1823 1650 1464 1351 1237 1226 1079 964 914 889 770 740 666 593 588 557 538 530 461 448 451 436 386 378 326 369 354 295 304 313 323 285 269 286 258 276 222 240 232 201 219 251 228 226 215 184 183 215 203 188 215 184 215 201 185 187 159 174 151 170 205 178 158 163 166 176 164 186 184 153 160 146 169 178 160 154 180 140 157 148 150 151 153 142 158 148 133 156 140 140 155 150 136 154 162 167 162 143 133 148 164 133 139 169 150 145 162 146 132 147 140 156 140 164 122 144 164 154 141 137 128 149 122 143 148 136 153 132 143 137 131 127 160 142 141 129 142 147 125 154 149 135 150 115 148 124 147 131 134 129 123 135 139 126 131 125 129 130 105 112 143 148 119 133 132 106 140 137 123 140 157 109 149 139 144 135 138 177 152 155 129 153 169 140 116 146 144 126 150 139 117 154 121 142 140 152 113 132 130 141 148 147 134 149 145 142 144 140 137 114 140 119 123 129 130 117 127 106 126 107 138 126 141 125 102 137 134 152 116 121 118 123 107 122 140 109 128 112 141 124 116 113 122 126 118 129 126 125 127 123 107 138 120 136 127 135 116 142 127 141 131 117 128 138 129 113 102 148 127 126 118 142 122 135 135 122 150 128 132 126 118 122 121 127 131 121 113 113 127 131 114 113 120 148 120 140 124 131 156 133 119 161 154 139 143 113 135 123 121 121 104 152 123 126 146 145 121 135 133 135 138 120 130 122 128 121 121 132 120 120 112 135 125 128 140 114 107 105 116 145 111 104 108 111 109 109 120 122 124 126 112 123 121 91 120 119 98 123 120 127 118 118 133 123 133 110 101 125 120 129 122 130 127 124 117 129 109 100 119 113 119 101 118 123 114 131 112 133 117 125 134 111 125 107 129 136 134 107 116 127 119 127 135 135 127 121 135 134 140 124 127 129 129 132 128 135 117 126 129 128 131 149 128 115 127 115 113 126 99 119 117 107 110 112 111 116 120 102 119 126 93 122 119 109 101 133 111 119 113 115 123 102 107 123 125 97 140 121 108 115 130 117 121 122 114 138 123 120 107 98 104 124 124 136 132 124 114 126 115 103 137 142 120 129 111 130 132 146 139 129 122 121 132 123 133 114 109 127 127 120 120 129 133 119 131 101 123 104 139 119 134 130 121 134 115 124 148 136 136 141 115 134 113 108 114 125 135 109 126 139 135 121 131 124 121 141 156 121 115 124 129 155 121 101 114 137 131 139 129 129 127 123 123 116 138 126 96 131 125 130 113 126 115 133 129 117 103 121 148 143 125 134 107 124 135 89 123 128 135 118 105 142 107 128 141 119 136 111 98 116 112 109 121 128 115 126 120 137 130 143 140 134 144 130 106 113 123 120 123 163 130 137 117 134 142 118 115 108 117 136 140 128 122 115 133 120 101 115 144 130 108 126 105 128 121 139 121 131 106 116 134 133 129 139 118 126 156 148 123 138 134 164 156 135 153 159 154 151 148 148 150 164 140 154 154 154 156 141 152 172 185 165 191 172 175 164 174 168 166 174 161 186 169 209 161 187 200 195 194 220 207 237 233 248 247 230 277 271 283 295 310 293 338 339 378 373 404 430 437 462 458 517 594 617 644 646 718 741 847 901 991 974 1107 1145 1240 1276 1452 1465 1544 1681 1786 1829 1869 2036 2130 2211 2195 2262 2225 2430 2315 2343 2438 2386 2439 2404 2350 2280 2287 2295 2226 2101 2116 2035 2060 1865 1760 1689 1585 1572 1488 1363 1270 1277 1076 1025 1009 960 900 821 792 702 655 636 561 572 511 499 422 431 429 405 366 366 328 333 350 270 279 257 287 262 238 244 192 194 241 204 199 181 163 175 180 168 170 144 165 148 129 146 142 164 161 140 159 134 167 161 146 157 158 135 155 142 128 123 134 126 114 163 125 129 136 124 129 127 120 120 129 121 130 111 122 109 119 114 107 123 128 130 103 139 122 121 123 147 97 128 121 127 124 123 122 117 128 122 110 125 112 123 111 110 102 112 128 102 116 121 129 103 104 119 113 97 98 103 123 116 120 105 105 85 113 103 96 105 107 98 103 109 98 107 110 107 99 87 96 91 97 97 95 99 87 102 104 87 100 89 100 94 106 95 110 115 111 101 91 104 110 93 92 110 87 98 103 103 87 75 90 96 109 88 87 91 97 109 102 94 91 89 108 111 100 102 104 94 80 115 101 95 105 101 109 103 100 93 106 95 121 91 107 102 79 84 95 86 92 100 91 108 91 71 104 108 104 87 95 103 90 105 95 101 89 112 96 97 97 79 107 107 104 105 110 110 102 98 110 109 98 113 86 77 99 101 95 99 94 97 114 84 95 101 81 95 93 84 107 100 99 100 106 109 124 98 99 97 93 91 99 105 99 114 88 86 107 104 95 105 107 94 75 95 88 87 103 121 106 102 80 82 96 72 69 79 87 91 91 86 102 91 99 97 90 94 101 98 84 85 80 104 81 91 94 111 94 89 112 96 112 100 93 89 86 72 102 93 84 82 113 87 85 91 105 103 91 96 80 104 98 100 94 88 81 100 78 76 89 93 93 96 99 125 79 82 81 82 70 76 117 89 87 91 95 76 96 78 95 97 103 67 93 104 90 80 85 81 93 106 77 87 109 80 85 94 88 78 80 104 100 78 83 79 74 81 94 97 75 83 89 79 110 92 107 95 84 85 78 88 93 83 78 104 82 85 84 86 75 107 95 101 68 91 91 88 95 72 89 100 97 92 94 101 102 102 69 97 90 88 77 97 89 82 81 87 104 73 99 95 96 99 73 106 93 85 94 65 97 91 86 92 95 81 88 99 102 89 99 104 101 101 101 83 97 89 81 73 85 91 94 86 96 101 99 96 85 99 79 105 104 83 74 100 78 86 80 79 83 93 95 118 90 93 79 100 92 90 85 87 97 99 98 85 102 77 85 82 94 78 71 93 105 80 92 81 93 69 92 101 80 71 74 82 88 92 92 82 84 80 76 87 93 80 76 71 79 80 66 92 68 78 81 70 91 78 76 84 85 75 78 82 78 94 97 94 91 62 88 77 72 88 82 84 86 77 76 91 101 90 80 105 102 86 88 90 93 83 66 72 106 72 72 87 92 68 92 89 72 77 95 75 78 82 85 82 83 64 86 88 112 82 87 67 87 83 93 87 75 77 81 79 85 100 78 86 83 83 77 80 85 82 80 89 91 69 94 77 74 87 73 87 84 69 88 74 81 78 86 77 90 88 71 92 107 89 97 76 89 92 85 88 58 82 74 80 65 71 74 71 78 86 83 70 95 72 76 82 71 80 62 64 93 72 92 65 81 89 88 89 76 76 72 85 68 82 85 94 86 79 82 85 84 74 82 80 71 60 54 79 80 92 85 84 66 86 70 73 68 63 73 65 86 72 86 82 76 70 87 95 73 72 74 81 92 81 68 69 70 80 81 105 89 74 89 93 82 74 76 82 75 72 86 85 61 87 67 93 92 94 105 81 84 87 83 81 76 79 85 83 79 81 88 80 89 66 59 93 87 79 67 88 93 72 86 70 93 75 81 88 93 89 73 73 82 79 83 79 92 69 82 70 75 60 70 77 75 81 63 98 75 89 62 74 81 73 72 67 91 69 74 81 89 83 84 61 64 82 85 77 90 58 91 71 94 88 78 89 69 98 96 91 86 77 76 89 82 93 93 77 80 75 80 74 67 94 78 67 70 85 87 86 78 74 97 83 74 80 70 74 103 83 71 73 70 92 95 78 81 60 71 87 74 83 89 80 98 77 74 77 76 68 80 70 63 76 75 74 83 73 88 88 73 68 77 69 77 92 69 71 79 72 65 66 61 89 64 69 71 60 70 69 60 66 71 84 68 82 58 84 69 90 83 74 81 77 81 66 93 60 65 79 74 83 72 74 74 74 79 79 79 80 84 82 70 82 75 68 91 87 99 74 85 90 84 68 76 68 85 77 77 66 75 88 65 92 65 71 62 63 85 67 71 58 76 67 67 76 82 73 90 67 76 87 78 70 69 69 65 74 78 69 71 75 76 75 90 90 61 74 59 85 73 65 74 76 75 73 80 82 80 75 63 69 79 60 86 72 75 83 77 82 84 86 65 64 67 83 75 73 68 84 57 64 59 71 76 54 80 66 63 66 63 65 46 73 80 62 76 62 87 75 83 77 67 76 70 76 61 81 65 73 73 79 78 69 67 74 69 71 76 73 62 69 77 60 72 68 75 74 67 67 78 82 76 72 65 76 75 79 80 57 62 77 62 78 86 90 59 97 65 67 71 65 73 57 64 68 82 67 87 71 69 97 81 68 83 88 115 87 75 86 72 74 83 77 73 103 71 86 97 90 87 97 101 107 77 106 75 102 76 97 99 74 88 90 101 90 91 76 98 87 96 87 88 77 101 72 74 94 82 71 87 93 73 70 76 61 77 84 72 62 72 73 78 67 87 80 75 67 76 74 75 65 75 88 87 64 74 75 65 70 87 70 83 61 64 74 76 83 102 74 64 77 63 76 79 74 75 92 90 87 66 81 83 74 66 72 78 81 78 71 80 87 68 78 82 66 66 70 58 59 58 68 68 73 78 72 80 67 67 72 78 64 74 81 77 61 65 71 74 65 67 75 92 85 72 87 62 60 72 57 56 73 76 76 67 70 69 62 53 67 63 74 72 67 75 68 74 75 73 71 73 66 67 82 64 60 58 58 63 57 79 65 59 76 85 77 58 72 76 54 67 73 70 58 70 72 68 68 70 71 62 66 77 65 71 76 76 63 71 69 78 75 64 70 79 74 75 62 67 74 68 65 76 79 74 77 58 66 76 65 76 70 64 73 78 81 77 77 66 58 52 77 49 72 72 59 47 59 63 86 71 79 60 78 61 72 81 72 78 87 63 68 73 74 75 68 68 63 72 58 74 72 64 60 69 72 64 58 73 74 60 82 62 74 75 63 86 86 78 69 69 67 85 79 69 67 61 68 72 59 83 74 76 71 81 75 97 76 63 88 73 76 67 74 70 70 58 69 53 80 82 72 86 82 59 61 57 72 64 82 89 82 81 72 56 59 67 78 57 72 68 67 73 57 66 59 60 72 70 63 54 72 73 85 77 71 80 58 72 61 61 58 67 65 62 67 61 74 63 75 61 63 64 56 61 67 63 67 66 64 73 59 63 62 80 65 74 75 63 58 73 61 58 56 66 52 70 71 64 54 68 55 60 71 73 55 69 76 61 69 58 63 68 71 62 74 58 66 54 76 72 69 65 66 77 73 66 75 81 83 60 60 67 65 76 78 57 56 65 89 70 63 65 76 67 62 68 63 59 63 68 64 73 57 81 66 79 60 76 86 79 63 76 71 57 65 79 75 65 59 68 77 74 70 58 78 65 79 85 70 70 70 68 71 70 68 74 69 79 75 76 77 73 74 80 79 67 54 61 66 75 62 86 74 70 62 65 80 78 73 57 70 77 58 81 88 63 79 73 67 76 57 52 75 56 74 73 72 82 61 65 62 63 61 69 59 69 64 70 57 80 56 81 60 50 61 62 57 68 59 65 71 55 72 72 77 71 63 63 75 64 72 59 70 55 76 64 78 78 65 66 62 63 73 84 68 60 63 64 89 73 55 67 65 79 36 60 64 69 94 58 52 65 50 76 67 72 75 77 62 61 50 76 92 70 75 77 62 75 76 59 75 70 70 75 60 72 82 61 78 78 72 68 63 59 71 61 86 58 60 63 58 64 61 78 77 74 75 64 60 58 60 70 72 73 74 68 70 77 78 64 43 64 77 85 50 59 72 60 76 62 57 76 65 57 68 57 53 65 69 68 57 73 51 75 52 77 56 72 67 56 61 70 69 82 73 36 80 61 58 70 73 76 64 78 73 71 57 59 66 71 44 65 67 61 79 76 65 53 67 73 58 63 62 62 61 88 68 56 55 58 45 63 74 69 66 77 67 55 65 55 61 61 69 62 80 48 72 53 74 73 71 49 87 54 67 60 63 76 73 59 73 62 63 63 74 65 80 76 91 64 82 65 71 58 62 57 79 56 63 69 85 59 61 85 59 67 65 66 88 42 68 68 61 75 62 54 58 70 74 57 50 81 78 57 59 65 78 78 66 75 51 75 68 72 66 59 80 66 61 54 63 80 55 61 76 56 66 62 75 67 58 67 62 76 63 74 65 68 71 82 50 69 48 71 66 61 62 87 61 76 75 68 59 55 69 65 54 66 56 60 73 60 83 46 75 57 74 70 78 79 57 58 67 56 59 70 38 49 59 68 66 92 57 71 62 81 68 65 68 76 82 80 57 89 79 58 56 47 69 73 66 68 57 62 60 65 69 68 90 56 58 71 60 65 63 64 68 54 72 68 59 80 66 75 77 71 52 65 68 49 72 60 66 62 53 67 55 77 62 70 69 69 53 64 66 58 64 63 59 66 76 61 63 61 66 75 62 65 67 67 72 65 63 58 66 62 73 46 58 61 52 67 70 59 72 72 68 53 70 79 59 58 69 63 68 59 73 69 57 66 65 62 76 73 63 70 62 73 59 68 50 69 56 59 73 64 68 55 73 44 60 66 84 73 70 58 68 67 67 71 74 73 63 63 65 68 69 68 69 73 63 56 64 69 71 58 70 69 72 75 72 72 80 56 71 69 66 73 76 74 66 74 67 61 56 85 63 66 79 68 74 76 62 69 66 82 70 69 77 75 95 75 69 61 48 63 71 83 68 74 78 63 78 83 67 73 52 63 58 64 62 76 65 69 65 74 67 76 81 63 84 72 70 77 75 69 87 81 76 86 83 75 66 85 72 78 81 72 65 78 75 66 90 68 69 76 65 84 73 70 61 67 70 75 83 72 64 64 76 59 66 70 76 57 73 67 71 60 66 85 51 68 86 88 60 82 50 76 78 70 51 69 68 66 64 71 67 68 78 79 75 85 64 76 68 57 83 63 72 77 82 73 68 76 67 71 71 65 61 78 80 53 71 50 82 76 87 86 79 61 87 62 78 73 75 68 75 65 89 88 65 97 79 86 83 69 66 80 81 81 89 75 84 76 75 111 73 90 77 81 69 80 71 89 90 77 83 75 81 85 63 92 88 81 73 72 74 93 81 91 97 77 72 90 94 77 77 80 96 74 79 89 84 95 89 81 98 73 89 90 74 86 104 92 95 85 96 89 104 104 91 112 109 105 79 88 103 103 120 114 107 120 126 104 114 93 138 121 128 131 139 147 144 159 137 141 163 171 177 173 176 193 198 211 220 206 216 244 213 250 241 275 271 274 302 296 354 338 368 401 414 448 463 478 504 496 533 587 612 645 633 663 736 748 784 768 869 874 973 917 1032 1002 961 988 986 1017 1030 1076 1095 1051 1008 1075 1074 1087 1053 1068 1056 988 993 972 946 962 913 925 931 881 837 814 780 799 769 721 728 696 640 676 662 630 545 565 554 476 481 479 447 405 450 412 383 358 345 317 272 280 251 258 242 267 221 211 222 184 206 205 162 181 151 182 160 162 155 137 147 146 137 141 148 145 113 130 112 104 123 111 115 102 102 116 126 113 90 101 118 83 90 93 93 95 92 97 88 96 76 86 103 90 85 100 106 71 85 93 87 79 83 83 74 90 84 90 78 76 73 84 86 82 85 91 73 95 71 66 84 84 75 71 83 82 75 75 78 69 73 78 83 77 69 106 68 74 76 84 68 77 87 86 58 82 78 87 77 62 77 77 91 71 71 68 76 72 62 68 74 62 62 66 56 77 80 69 71 66 71 55 72 83 67 63 62 88 71 72 80 66 74 80 70 79 62 79 85 58 68 59 64 88 69 57 64 70 73 70 69 67 68 61 66 83 79 63 58 59 62 69 38 65 63 78 77 68 76 70 66 54 85 66 76 87 80 73 84 75 91 71 73 72 68 70 60 56 65 74 65 63 76 43 69 73 81 56 64 67 70 57 82 74 57 68 86 61 75 68 79 68 58 60 67 66 76 62 67 85 72 70 58 78 71 76 73 57 70 60 75 74 75 52 64 70 61 67 60 62 61 61 69 69 64 80 75 76 64 68 64 72 68 76 52 74 62 61 79 65 52 67 84 63 58 80 63 81 75 73 76 72 57 70 71 57 63 73 72 73 63 67 73 69 70 69 58 63 68 60 69 55 64 75 81 58 70 65 68 66 62 62 68 71 79 64 65 60 64 73 54 61 60 56 74 60 81 53 72 47 66 61 66 73 64 81 70 64 57 53 67 74 60 63 64 75 60 62 78 67 61 73 64 66 63 65 60 60 68 74 66 69 67 67 63 70 66 71 92 57 65 63 48 71 67 69 54 58 63 60 62 50 70 61 49 62 68 65 58 64 65 47 68 69 63 55 61 78 73 63 67 65 50 68 65 68 56 59 59 68 74 64 63 80 61 72 63 69 82 62 66 67 68 61 71 71 66 58 54 56 63 62 65 58 67 65 58 64 69 65 71 67 63 68 77 69 66 71 79 73 59 50 70 69 67 65 75 70 65 76 59 63 65 70 74 74 56 62 74 61 67 62 73 73 60 51 67 68 78 79 72 67 61 69 65 72 78 85 62 74 77 71 73 86 60 75 79 75 66 81 75 64 75 86 73 86 80 78 57 72 68 59 71 67 67 77 56 78 77 61 61 75 70 69 72 65 73 54 52 59 72 54 59 77 57 62 69 53 62 62 55 76 67 50 65 58 73 55 66 65 56 66 65 56 72 64 51 55 50 57 61 72 72 62 71 71 58 64 65 61 71 69 68 68 61 53 62 64 58 62 59 58 64 68 66 49 63 50 73 64 46 56 61 69 68 64 66 46 74 61 70 63 59 65 69 59 82 69 59 47 56 74 68 63 64 72 56 57 58 63 59 66 68 74 61 65 59 68 69 56 62 59 64 61 59 66 79 55 54 63 48 61 54 63 60 62 64 52 63 56 56 58 67 48 64 62 67 70 67 70 66 54 50 56 61 51 46 52 62 67 56 78 64 68 50 60 65 65 59 51 70 53 66 70 84 69 67 70 60 57 80 64 83 46 54 73 62 51 58 65 67 48 65 80 64 45 64 68 59 60 60 62 63 67 58 80 68 70 46 65 67 74 54 58 64 56 73 54 69 64 63 73 79 69 54 47 65 68 57 83 59 68 62 79 65 61 55 56 73 80 72 67 44 73 71 71 75 67 45 71 57 56 72 58 62 68 80 56 79 62 58 66 67 78 51 52 56 61 79 66 73 53 71 57 63 64 52 50 67 65 64 65 63 60 55 60 50 75 66 55 63 77 73 60 75 83 61 72 56 55 62 54 61 74 79 55 72 69 55 47 56 75 50 68 60 68 59 66 65 58 59 62 60 51 68 58 74 62 60 60 59 67 68 74 66 82 66 66 56 67 68 55 81 63 69 62 70 54 72 65 64 67 52 57 55 63 70 52 64 70 57 73 67 70 68 59 74 64 68 63 60 70 49 58 74 67 60 59 55 72 53 67 73 55 73 62 74 64 54 64 59 68 59 60 64 65 55 57 68 59 53 62 72 66 69 70 56 67 61 68 60 74 75 61 58 51 66 66 58 57 72 76 61 58 75 63 57 57 89 54 69 64 64 61 53 66 56 66 77 46 70 79 66 65 69 65 66 64 74 54 64 68 62 54 73 41 76 76 60 50 65 70 68 61 46 64 57 58 64 61 55 73 61 71 65 73 79 78 71 75 63 61 53 76 82 53 62 72 67 53 62 66 61 74 83 56 70 57 82 71 61 49 69 62 70 62 59 69 57 65 59 61 56 55 63 51 60 63 59 61 52 63 62 73 63 56 65 60 64 46 61 58 58 62 62 57 50 59 73 52 61 67 67 65 67 46 78 66 70 63 68 53 68 65 63 66 47 59 78 61 59 69 63 63 74 80 58 51 61 59 60 83 68 68 65 61 73 79 61 78 63 46 47 63 74 68 59 51 60 62 71 58 69 71 63 69 70 75 63 61 68 71 70 62 65 62 60 60 76 67 61 63 64 50 66 44 63 60 57 65 50 46 52 56 63 64 81 65 65 54 73 69 69 81 72 57 60 69 64 69 78 72 62 66 58 70 76 56 69 67 69 60 74 76 63 58 64 53 71 59 68 69 64 67 49 64 68 67 61 67 65 75 72 72 67 63 70 72 56 55 68 72 75 56 66 63 73 61 92 70 82 75 83 62 71 69 81 62 57 76 57 92 90 76 75 74 69 88 59 64 68 63 61 59 69 65 66 53 62 60 62 58 54 70 62 78 62 60 82 68 67 63 77 69 70 67 72 65 73 47 62 65 62 85 65 74 63 75 80 59 70 74 74 71 79 63 82 71 81 78 73 61 64 74 79 76 61 70 78 64 68 71 74 55 81 65 80 65 62 65 74 78 87 60 85 63 79 81 85 62 60 74 89 66 71 83 61 71 78 77 60 85 70 60 66 65 51 61 75 77 71 68 66 65 90 86 61 52 81 66 78 61 90 67 71 62 67 63 76 78 83 70 71 67 69 72 64 65 62 60 69 60 81 65 81 80 70 80 61 61 70 83 74 67 71 73 73 61 67 77 81 80 87 70 80 70 66 87 58 63 54 63 67 68 80 71 68 80 81 53 83 62 75 69 68 76 83 69 92 74 79 67 70 67 76 69 69 81 55 65 78 62 69 78 71 85 96 74 85 80 81 76 85 74 71 75 76 72 78 72 74 71 70 90 75 81 69 82 77 86 84 64 81 90 80 78 93 85 80 67 76 95 86 103 75 81 80 88 90 71 88 85 90 109 94 112 93 82 70 89 102 96 90 99 104 97 107 107 101 98 104 87 99 121 108 104 103 114 106 117 98 126 120 114 136 129 125 124 118 128 139 171 141 159 165 144 138 151 165 155 174 169 150 173 200 190 195 195 257 211 236 271 247 231 256 268 267 291 289 312 308 354 325 350 389 390 418 392 458 405 510 502 552 511 583 575 573 635 673 687 672 646 746 770 756 772 790 799 855 830 879 918 863 824 848 886 898 892 848 887 861 847 895 863 823 829 868 856 797 818 791 773 783 791 737 745 757 724 714 652 678 688 654 637 638 602 633 577 568 598 539 529 527 510 511 461 435 402 423 412 351 359 389 376 363 310 326 365 308 243 243 292 269 236 269 217 199 233 203 187 184 164 170 159 146 161 166 143 165 153 135 138 112 133 128 145 120 136 98 141 104 117 127 136 108 113 88 112 105 98 103 105 117 113 96 85 117 83 96 89 90 91 88 85 72 77 93 101 87 91 85 98 87 100 72 81 93 78 93 76 84 75 118 89 88 64 82 97 88 65 75 85 85 72 83 79 87 74 67 86 77 66 63 70 66 69 79 95 77 87 57 77 71 85 61 83 86 82 75 72 77 78 82 91 67 96 77 73 79 79 70 71 79 81 75 71 89 72 72 64 62 74 60 80 60 85 66 61 66 82 78 78 75 77 75 78 62 80 76 77 60 78 66 86 98 84 58 74 87 69 62 74 60 63 74 73 72 70 61 66 70 82 79 82 61 80 56 69 66 64 70 71 71 77 86 77 88 70 66 76 76 80 67 75 75 58 62 74 66 79 88 74 70 78 72 82 68 72 74 73 81 71 63 74 73 73 65 62 67 73 67 67 65 64 60 69 64 69 76 76 58 53 82 75 74 67 76 70 68 71 72 70 67 61 76 70 66 57 65 64 59 72 62 65 78 67 66 63 71 60 68 73 76 76 74 59 76 63 101 73 70 81 56 75 76 86 73 56 66 57 71 60 77 62 74 87 59 68 57 73 69 85 62 69 58 66 61 74 72 90 81 66 61 64 55 58 83 71 60 80 80 64 86 69 48 60 79 65 66 72 59 80 66 63 62 56 70 68 76 92 64 80 66 61 82 70 86 59 81 65 75 60 74 83 67 68 74 47 72 74 74 55 71 59 74 67 66 93 65 78 70 82 78 75 82 80 84 64 69 59 83 82 76 72 88 74 92 83 70 65 64 84 82 66 85 84 79 91 82 87 80 81 71 83 83 79 62 93 81 87 90 86 89 88 88 102 95 101 85 90 77 94 113 104 90 116 114 117 116 116 107 129 130 128 122 143 135 155 151 151 137 156 143 183 181 184 188 183 170 200 223 200 194 196 211 247 244 267 236 223 271 259 306 288 307 292 274 286 310 320 289 278 278 289 277 352 280 256 303 298 285 282 277 277 284 260 297 212 259 230 284 226 245 276 233 237 235 247 242 247 241 225 188 236 216 209 173 199 218 187 169 184 180 159 163 159 161 165 138 140 123 142 133 126 112 120 116 135 118 118 101 110 91 94 116 102 104 85 107 103 86 102 96 96 80 87 99 82 84 85 76 86 77 77 80 70 83 103 85 80 63 70 78 64 71 65 76 79 68 69 64 77 79 72 79 67 75 77 60 87 71 61 69 79 63 69 75 63 65 77 55 67 71 59 73 58 64 51 74 67 72 54 68 71 55 56 62 71 56 70 71 85 62 63 80 68 64 51 73 59 82 63 73 52 80 71 79 60 60 74 56 64 66 69 58 65 58 69 59 78 66 62 82 47 64 51 70 55 73 63 59 74 55 58 60 58 76 77 76 67 66 60 70 72 57 56 54 60 44 59 57 50 64 68 64 66 69 71 72 56 50 70 62 60 65 61 63 72 76 71 71 57 49 66 65 61 59 59 68 67 56 62 86 67 62 67 66 73 67 68 50 61 82 62 73 60 62 51 61 53 66 64 82 56 67 64 79 61 57 60 49 66 74 68 52 68 77 62 66 62 68 58 61 51 64 68 56 58 52 60 79 57 59 67 57 66 61 63 58 69 48 57 74 67 69 53 73 61 52 75 53 65 69 72 66 63 59 78 73 49 50 68 55 54 48 63 57 71 65 52 54 70 53 66 55 62 58 48 72 55 66 62 71 53 41 49 66 61 68 57 64 53 72 44 62 57 65 56 65 65 54 59 55 58 61 53 58 67 59 53 61 71 73 48 78 82 58 71 46 57 65 59 59 62 59 54 56 52 65 63 52 79 64 56 52 47 68 67 58 54 42 58 56 62 61 66 65 53 42 55 65 68 67 51 71 56 52 64 63 51 71 57 57 62 61 56 64 55 62 59 56 48 48 52 51 66 51 58 64 78 52 55 62 50 70 59 60 67 53 52 62 45 60 52 45 65 62 60 53 39 60 61 60 58 62 65 54 69 59 58 69 55 54 54 60 52 57 62 58 67 48 60 60 53 73 63 52 60 60 70 53 40 62 64 68 54 67 63 65 64 61 55 67 60 55 71 51 55 58 55 65 45 60 67 47 49 62 52 55 56 55 58 53 56 59 55 60 50 54 54 53 58 75 57 58 46 59 64 65 61 69 68 58 61 60 74 71 53 64 63 67 52 45 50 62 64 61 59 47 68 54 57 51 65 69 67 61 60 54 46 70 66 56 62 55 63 53 59 51 58 64 64 64 52 48 41 43 61 55 57 49 52 56 59 79 56 69 45 66 60 55 65 58 58 57 67 52 51 54 44 60 64 56 56 69 55 62 63 52 49 61 61 57 54 72 44 52 73 52 66 61 59 52 63 51 55 57 53 62 60 70 63 71 57 50 60 69 73 50 55 50 65 64 51 66 64 61 61 54 53 75 54 53 59 59 55 64 58 49 47 50 57 53 56 63 57 62 68 67 55 53 52 65 66 69 43 57 65 63 65 58 52 54 51 60 63 61 52 44 50 52 54 55 41 52 55 64 54 57 59 70 43 51 55 59 47 58 70 54 63 35 53 50 58 61 55 58 60 55 49 63 58 57 56 60 62 62 60 58 45 54 57 49 59 53 61 68 44 59 49 52 60 51 74 57 52 55 59 55 52 46 50 39 61 51 47 49 49 59 55 44 67 59 65 57 59 61 57 68 53 65 34 61 65 53 38 46 75 56 43 61 73 81 71 68 44 49 51 60 73 52 57 49 49 59 53 52 58 64 64 54 53 56 59 52 60 35 64 43 78 46 49 59 57 50 72 49 69 51 53 49 59 70 65 47 53 56 47 72 65 53 66 57 41 51 53 47 71 54 43 52 57 57 55 58 50 51 70 57 64 57 53 54 57 57 76 71 71 46 56 71 61 52 58 55 83 53 69 58 61 62 53 50 43 57 71 50 75 62 56 57 68 49 66 46 47 50 47 57 62 56 49 46 67 60 65 51 65 55 62 53 69 52 54 62 57 50 64 57 61 61 58 69 56 59 66 64 48 61 50 55 65 52 61 46 54 49 67 56 60 60 56 57 72 74 55 62 38 64 46 63 51 62 49 61 61 61 75 44 50 40 64 51 66 74 63 60 57 69 43 54 56 44 66 65 74 51 49 50 65 45 55 60 65 69 52 74 51 63 56 55 66 56 54 66 50 42 51 57 65 45 57 59 48 57 55 59 56 43 57 56 56 68 66 55 60 43 57 51 55 52 56 55 65 58 64 55 63 61 59 62 61 67 53 66 63 53 60 56 64 56 61 46 59 48 71 64 60 51 59 48 41 65 55 58 62 46 46 55 58 49 54 47 50 62 45 65 64 60 56 56 55 43 49 65 65 70 53 55 49 58 56 53 57 69 56 55 49 75 60 49 52 61 47 38 66 74 55 59 49 57 64 70 48 60 50 71 47 55 53 66 63 54 57 58 62 40 46 59 59 57 47 55 62 40 65 51 70 63 66 58 47 53 60 47 58 69 57 66 44 69 65 44 56 52 68 45 51 61 48 71 52 62 59 61 56 41 53 43 51 59 63 79 54 56 58 46 62 42 47 65 62 49 49 64 61 60 47 50 63 43 60 70 55 62 39 57 45 64 58 54 44 51 63 55 59 59 49 58 49 58 60 52 59 59 51 46 56 57 58 48 53 52 62 51 56 71 63 52 69 53 60 54 71 70 58 63 57 44 73 53 65 46 53 59 40 47 43 44 55 46 56 50 56 56 55 58 53 54 49 47 48 55 68 42 48 49 59 46 66 45 52 59 57 59 61 58 60 56 49 64 52 57 49 54 53 50 68 63 47 66 59 63 52 43 60 59 52 47 58 54 75 53 52 62 52 50 54 66 51 59 64 62 45 44 68 57 61 57 63 54 69 62 46 49 55 52 55 56 59 48 62 54 62 62 53 59 48 59 49 50 61 51 51 64 55 57 52 48 51 46 32 56 54 56 58 55 48 53 48 56 58 70 45 66 64 64 68 55 59 60 53 53 60 62 51 49 59 55 44 64 50 60 61 49 59 38 46 44 48 49 48 58 52 65 49 49 55 57 56 41 54 48 51 56 49 43 62 58 50 54 69 53 63 61 56 59 56 66 58 57 50 33 51 59 55 48 63 63 79 52 65 61 46 62 54 71 54 59 50 44 57 41 51 46 58 55 53 64 46 56 54 53 59 53 57 50 47 86 61 42 63 69 55 63 45 68 45 59 69 71 56 49 62 60 64 52 53 49 54 64 59 53 63 54 65 66 49 58 57 40 46 74 47 47 63 56 44 52 52 52 53 42 48 63 45 51 57 56 52 61 49 76 53 46 67 54 57 55 66 40 53 58 52 48 51 54 55 60 66 53 55 57 54 56 64 62 65 81 55 43 50 46 60 49 58 59 41 53 55 70 60 50 57 52 63 57 51 71 53 62 70 60 65 61 58 45 58 54 56 44 57 61 56 57 48 63 57 54 68 66 51 60 45 54 50 67 53 57 50 67 54 51 53 57 56 61 57 53 70 53 45 55 58 68 65 68 61 51 47 51 64 66 59 47 45 51 49 53 61 52 62 55 62 53 47 64 67 45 52 64 54 50 58 48 53 76 50 51 56 55 47 56 63 50 76 56 52 55 51 53 56 57 66 66 56 52 47 58 63 64 56 54 63 66 55 67 46 45 45 51 75 57 68 53 54 75 74 55 63 47 51 56 63 55 47 64 48 38 55 45 66 45 57 41 50 56 64 60 52 60 49 36 48 49 64 56 65 50 79 55 66 57 46 56 55 52 54 46 61 52 52 62 64 45 51 59 56 61 42 51 61 65 50 48 65 59 53 70 67 58 64 74 40 50 54 67 56 71 53 54 70 57 53 49 53 65 58 53 46 58 48 54 58 56 62 56 57 45 57 36 42 57 60 62 62 70 55 56 52 47 60 59 49 57 66 58 46 67 53 62 72 67 52 49 46 53 63 61 49 51 60 51 50 53 70 49 59 56 66 74 47 61 53 50 57 60 68 69 63 63 49 56 70 64 57 46 51 53 54 55 64 69 65 73 51 63 54 41 55 41 42 70 69 47 53 55 57 51 62 67 60 50 50 61 55 48 53 62 68 56 53 58 64 53 49 48 53 56 51 63 52 64 61 46 57 49 60 66 50 47 53 54 63 61 61 51 51 66 62 53 55 48 50 65 45 53 43 48 68 67 56 54 59 48 63 51 55 72 58 70 55 60 47 54 51 65 72 66 65 48 56 67 45 43 55 63 53 52 54 53 70 46 48 55 43 51 72 46 62 59 49 51 53 57 71 63 57 68 64 53 63 42 55 53 82 71 59 56 58 58 80 61 61 74 68 64 59 56 63 59 69 57 54 71 74 57 78 69 59 48 57 72 59 57 66 69 52 72 67 72 65 64 54 63 74 69 71 64 77 95 74 78 76 72 65 71 62 75 86 73 98 62 88 66 93 82 82 96 93 93 66 87 103 104 66 101 93 99 105 89 96 96 94 120 99 89 114 104 92 120 119 119 108 129 122 134 151 131 141 129 114 130 104 144 119 126 111 138 143 147 131 138 108 129 145 141 147 131 105 144 129 111 128 143 133 109 134 124 121 136 119 122 111 116 105 122 116 118 118 130 124 89 103 130 106 113 112 129 112 117 108 98 91 115 90 92 105 94 105 95 110 93 95 110 92 94 90 82 87 100 88 81 77 86 83 80 78 78 82 100 67 79 89 79 57 78 71 73 78 64 73 89 82 65 71 52 65 65 74 70 77 72 73 60 90 66 72 70 60 83 63 62 69 59 72</intensities>
			</dataPoints>
		</scan>
	</xrdMeasurement>
</xrdMeasurements>